Workbook
Name \0: #REF!
Name \0: 'Inlet Spacing_10-yr'!$D$46
Name \0: 'Inlet Spacing_2-yr'!$D$46
Name \0: 'MD 410 Inlet Drainage Calcs'!$C$38
Name \0: #REF!
Name \c: #REF!
Name \c: 'Inlet Spacing_10-yr'!$H$53
Name \c: 'Inlet Spacing_2-yr'!$H$53
Name \c: 'MD 410 Inlet Drainage Calcs'!$G$45
Name \c: #REF!
Name \e: #REF!
Name \e: 'Inlet Spacing_10-yr'!$H$48
Name \e: 'Inlet Spacing_2-yr'!$H$48
Name \e: 'MD 410 Inlet Drainage Calcs'!$G$40
Name \e: #REF!
Name \p: #REF!
Name \p: 'Inlet Spacing_10-yr'!$H$67
Name \p: 'Inlet Spacing_2-yr'!$H$67
Name \p: 'MD 410 Inlet Drainage Calcs'!$G$59
Name \p: #REF!
Name \r: #REF!
Name \r: 'Inlet Spacing_10-yr'!$C$56
Name \r: 'Inlet Spacing_2-yr'!$C$56
Name \r: 'MD 410 Inlet Drainage Calcs'!$B$48
Name \r: #REF!
Name _DUR1: '[1]Q peak i1-4'!$C$10
Name _DUR1: '[2]Q peak i1-4'!$C$10
Name _DUR10: '[1]Q peak i9-12'!$C$17
Name _DUR10: '[2]Q peak i9-12'!$C$17
Name _DUR11: '[1]Q peak i9-12'!$C$24
Name _DUR11: '[2]Q peak i9-12'!$C$24
Name _DUR12: '[1]Q peak i9-12'!$C$31
Name _DUR13: '[1]Q peak i13-16'!$C$10
Name _DUR13: '[2]Q peak i13-16'!$C$10
Name _DUR14: '[1]Q peak i13-16'!$C$17
Name _DUR14: '[2]Q peak i13-16'!$C$17
Name _DUR15: '[1]Q peak i13-16'!$C$24
Name _DUR15: '[2]Q peak i13-16'!$C$24
Name _DUR16: '[1]Q peak i13-16'!$C$31
Name _DUR16: '[2]Q peak i13-16'!$C$31
Name _DUR17: #REF!
Name _DUR17: #REF!
Name _DUR18: #REF!
Name _DUR18: #REF!
Name _DUR2: '[1]Q peak i1-4'!$C$17
Name _DUR2: '[2]Q peak i1-4'!$C$17
Name _DUR3: '[1]Q peak i1-4'!$C$24
Name _DUR3: '[2]Q peak i1-4'!$C$24
Name _DUR4: '[1]Q peak i1-4'!$C$31
Name _DUR4: '[2]Q peak i1-4'!$C$31
Name _DUR5: '[1]Q peak i5-8'!$C$10
Name _DUR5: '[2]Q peak i5-8'!$C$10
Name _DUR6: '[1]Q peak i5-8'!$C$17
Name _DUR6: '[2]Q peak i5-8'!$C$17
Name _DUR7: '[1]Q peak i5-8'!$C$24
Name _DUR7: '[2]Q peak i5-8'!$C$24
Name _DUR8: '[1]Q peak i5-8'!$C$31
Name _DUR8: '[2]Q peak i5-8'!$C$31
Name _DUR9: '[1]Q peak i9-12'!$C$10
Name _DUR9: '[2]Q peak i9-12'!$C$10

Sheet MD 410 Inlet Drainage Calcs
G1: COG AND COS INLET SPACING SPREADSHEET
A4: PROJECT: | C4: Second Avenue | J4: GUTTER DEPRESSION = | M4: 0.125 | N4: FEET | V4: REQUIRED LENGTH FOR
L5: N = | M5: 0.015 | V5: TOTAL INTERCEPTION
A6: CONTRACT NO. : | G6: STORM FREQUENCY: 2 - YEAR | K6: GUTTER WIDTH = | M6: 1 | N6: FEET
V7: if L>=15 | X7: if a=0
A8: INLET | B8: INLET | C8: AREA | F8: BYPASS | G8: TOTAL | H8: T.O.C. | I8: I | J8: Q | K8: XSLOPE | L8: GRADE | M8: SPREAD | N8: PICKUP | O8: BYPASS | P8: BYPASS | S8: relative | T8: flow ratio | U8: equivalent | V8: k=0.54,else | X8: k=0.60,else | Y8: intercept
A9: NUMBER | B9: LENGTH | C9: (acres) | D9: C | E9: CA | F9: CA | G9: CA | H9: (MIN) | I9: (IN/HR) | J9: (CFS) | K9: (FT/FT) | L9: (FT/FT) | M9: (FT) | N9: % | O9: CA | P9: TO | S9: X-slope | U9: X-slope | V9: k=0.58 | W9: k=0.58 | X9: see V | Y9: efficiency
A11: I-03A | B11: 5 | C11: 0.06 | D11: 0.86 | E11: =IF(AND(C11=0,D11=0)," ",+C11*D11) -> 0.0516 | F11: =IF(AND(C11=0,D11=0)," ",+AC32) -> 0 | G11: =IF(AND(C11=0,D11=0)," ",+E11+F11) -> 0.0516 | H11: 5 | I11: 7.07 | J11: =IF(AND(C11=0,D11=0)," ",+G11*I11) -> 0.364812 | K11: 0.02 | L11: 0.012 | M11: =IF(AND(C11=0,D11=0)," ",+K34) -> 4.6717466 | N11: =IF(AND(C11=0,D11=0)," ",O34) -> 94.388275 | O11: =IF(AND(C11=0,D11=0)," ",+G11*(1-(N11/100))) -> 0.0028956503 | R11: =K11+0.25*(1-(1-$M$6/M11)^2.67) -> 0.13858636 | S11: =($M$4+K11*$M$6)/$M$6 -> 0.145 | T11: =($M$4/($M$4+$M$6*K11))*(0.56/$M$5*S11^1.667*L11^0.5*$M$6^2.667)/J11 -> 0.38651001 | U11: =K11+($M$4/$M$6)*T11 -> 0.068313751 | V11: =IF(B11>=15,0.54*J11^0.42*L11^0.3*(1/($M$5*U11))^0.6,W11) -> 6.2645771 | W11: =0.58*J11^0.42*L11^0.3*(1/($M$5*U11))^0.6 -> 6.2645771 | X11: =IF($M$4=0,0.6*J11^0.42*L11^0.3*(1/($M$5*U11))^0.6,V11) -> 6.2645771 | Y11: =IF(B11>X11,1,1-(1-B11/X11)^1.8) -> 0.94388275 | AB11: =IF(EXACT($A$11,$P11),$O11,0) -> #VALUE! | AC11: =IF(ISERR(AB11),0,AB11) -> 0 | AD11: =IF(EXACT($A$12,$P11),$O11,0) -> #VALUE! | AE11: =IF(ISERR(AD11),0,AD11) -> 0 | AF11: =IF(EXACT($A$13,$P11),$O11,0) -> #VALUE! | AG11: =IF(ISERR(AF11),0,AF11) -> 0 | AH11: =IF(EXACT($A$14,$P11),$O11,0) -> #VALUE! | AI11: =IF(ISERR(AH11),0,AH11) -> 0 | AJ11: =IF(EXACT($A$15,$P11),$O11,0) -> #VALUE! | AK11: =IF(ISERR(AJ11),0,AJ11) -> 0 | AL11: =IF(EXACT($A$16,$P11),$O11,0) -> #VALUE! | AM11: =IF(ISERR(AL11),0,AL11) -> 0 | AN11: =IF(EXACT($A$17,$P11),$O11,0) -> #VALUE! | AO11: =IF(ISERR(AN11),0,AN11) -> 0 | AP11: =IF(EXACT($A$18,$P11),$O11,0) -> #VALUE! | AQ11: =IF(ISERR(AP11),0,AP11) -> 0 | AR11: =IF(EXACT($A$19,$P11),$O11,0) -> #VALUE! | AS11: =IF(ISERR(AR11),0,AR11) -> 0 | AT11: =IF(EXACT($A$20,$P11),$O11,0) -> #VALUE! | AU11: =IF(ISERR(AT11),0,AT11) -> 0 | AV11: =IF(EXACT($A$21,$P11),$O11,0) -> #VALUE! | AW11: =IF(ISERR(AV11),0,AV11) -> 0 | AX11: =IF(EXACT($A$22,$P11),$O11,0) -> #VALUE! | AY11: =IF(ISERR(AX11),0,AX11) -> 0 | AZ11: =IF(EXACT($A$23,$P11),$O11,0) -> #VALUE! | BA11: =IF(ISERR(AZ11),0,AZ11) -> 0 | BB11: =IF(EXACT($A$24,$P11),$O11,0) -> #VALUE! | BC11: =IF(ISERR(BB11),0,BB11) -> 0 | BD11: =IF(EXACT($A$25,$P11),$O11,0) -> #VALUE! | BE11: =IF(ISERR(BD11),0,BD11) -> 0 | BF11: =IF(EXACT($A$26,$P11),$O11,0) -> #VALUE! | BG11: =IF(ISERR(BF11),0,BF11) -> 0 | BH11: =IF(EXACT($A$27,$P11),$O11,0) -> #VALUE! | BI11: =IF(ISERR(BH11),0,BH11) -> 0 | BJ11: =IF(EXACT($A$28,$P11),$O11,0) -> #VALUE! | BK11: =IF(ISERR(BJ11),0,BJ11) -> 0 | BL11: =IF(EXACT($A$29,$P11),$O11,0) -> #VALUE! | BM11: =IF(ISERR(BL11),0,BL11) -> 0 | BN11: =IF(EXACT($A$30,$P11),$O11,0) -> #VALUE! | BO11: =IF(ISERR(BN11),0,BN11) -> 0
R12: =K12+0.25*(1-(1-$M$6/M12)^2.67) -> #DIV/0! | S12: =($M$4+K12*$M$6)/$M$6 -> 0.125 | T12: =($M$4/($M$4+$M$6*K12))*(0.56/$M$5*S12^1.667*L12^0.5*$M$6^2.667)/J12 -> #DIV/0! | U12: =K12+($M$4/$M$6)*T12 -> #DIV/0! | V12: =IF(B12>=15,0.54*J12^0.42*L12^0.3*(1/($M$5*U12))^0.6,W12) -> #DIV/0! | W12: =0.58*J12^0.42*L12^0.3*(1/($M$5*U12))^0.6 -> #DIV/0! | X12: =IF($M$4=0,0.6*J12^0.42*L12^0.3*(1/($M$5*U12))^0.6,V12) -> #DIV/0! | Y12: =IF(B12>X12,1,1-(1-B12/X12)^1.8) -> #DIV/0! | AB12: =IF(EXACT($A$11,$P12),$O12,0) -> #VALUE! | AC12: =IF(ISERR(AB12),0,AB12) -> 0 | AD12: =IF(EXACT($A$12,$P12),$O12,0) -> #VALUE! | AE12: =IF(ISERR(AD12),0,AD12) -> 0 | AF12: =IF(EXACT($A$13,$P12),$O12,0) -> #VALUE! | AG12: =IF(ISERR(AF12),0,AF12) -> 0 | AH12: =IF(EXACT($A$14,$P12),$O12,0) -> #VALUE! | AI12: =IF(ISERR(AH12),0,AH12) -> 0 | AJ12: =IF(EXACT($A$15,$P12),$O12,0) -> #VALUE! | AK12: =IF(ISERR(AJ12),0,AJ12) -> 0 | AL12: =IF(EXACT($A$16,$P12),$O12,0) -> #VALUE! | AM12: =IF(ISERR(AL12),0,AL12) -> 0 | AN12: =IF(EXACT($A$17,$P12),$O12,0) -> #VALUE! | AO12: =IF(ISERR(AN12),0,AN12) -> 0 | AP12: =IF(EXACT($A$18,$P12),$O12,0) -> #VALUE! | AQ12: =IF(ISERR(AP12),0,AP12) -> 0 | AR12: =IF(EXACT($A$19,$P12),$O12,0) -> #VALUE! | AS12: =IF(ISERR(AR12),0,AR12) -> 0 | AT12: =IF(EXACT($A$20,$P12),$O12,0) -> #VALUE! | AU12: =IF(ISERR(AT12),0,AT12) -> 0 | AV12: =IF(EXACT($A$21,$P12),$O12,0) -> #VALUE! | AW12: =IF(ISERR(AV12),0,AV12) -> 0 | AX12: =IF(EXACT($A$22,$P12),$O12,0) -> #VALUE! | AY12: =IF(ISERR(AX12),0,AX12) -> 0 | AZ12: =IF(EXACT($A$23,$P12),$O12,0) -> #VALUE! | BA12: =IF(ISERR(AZ12),0,AZ12) -> 0 | BB12: =IF(EXACT($A$24,$P12),$O12,0) -> #VALUE! | BC12: =IF(ISERR(BB12),0,BB12) -> 0 | BD12: =IF(EXACT($A$25,$P12),$O12,0) -> #VALUE! | BE12: =IF(ISERR(BD12),0,BD12) -> 0 | BF12: =IF(EXACT($A$26,$P12),$O12,0) -> #VALUE! | BG12: =IF(ISERR(BF12),0,BF12) -> 0 | BH12: =IF(EXACT($A$27,$P12),$O12,0) -> #VALUE! | BI12: =IF(ISERR(BH12),0,BH12) -> 0 | BJ12: =IF(EXACT($A$28,$P12),$O12,0) -> #VALUE! | BK12: =IF(ISERR(BJ12),0,BJ12) -> 0 | BL12: =IF(EXACT($A$29,$P12),$O12,0) -> #VALUE! | BM12: =IF(ISERR(BL12),0,BL12) -> 0 | BN12: =IF(EXACT($A$30,$P12),$O12,0) -> #VALUE! | BO12: =IF(ISERR(BN12),0,BN12) -> 0
R13: =K13+0.25*(1-(1-$M$6/M13)^2.67) -> #DIV/0! | S13: =($M$4+K13*$M$6)/$M$6 -> 0.125 | T13: =($M$4/($M$4+$M$6*K13))*(0.56/$M$5*S13^1.667*L13^0.5*$M$6^2.667)/J13 -> #DIV/0! | U13: =K13+($M$4/$M$6)*T13 -> #DIV/0! | V13: =IF(B13>=15,0.54*J13^0.42*L13^0.3*(1/($M$5*U13))^0.6,W13) -> #DIV/0! | W13: =0.58*J13^0.42*L13^0.3*(1/($M$5*U13))^0.6 -> #DIV/0! | X13: =IF($M$4=0,0.6*J13^0.42*L13^0.3*(1/($M$5*U13))^0.6,V13) -> #DIV/0! | Y13: =IF(B13>X13,1,1-(1-B13/X13)^1.8) -> #DIV/0! | AB13: =IF(EXACT($A$11,$P13),$O13,0) -> #VALUE! | AC13: =IF(ISERR(AB13),0,AB13) -> 0 | AD13: =IF(EXACT($A$12,$P13),$O13,0) -> #VALUE! | AE13: =IF(ISERR(AD13),0,AD13) -> 0 | AF13: =IF(EXACT($A$13,$P13),$O13,0) -> #VALUE! | AG13: =IF(ISERR(AF13),0,AF13) -> 0 | AH13: =IF(EXACT($A$14,$P13),$O13,0) -> #VALUE! | AI13: =IF(ISERR(AH13),0,AH13) -> 0 | AJ13: =IF(EXACT($A$15,$P13),$O13,0) -> #VALUE! | AK13: =IF(ISERR(AJ13),0,AJ13) -> 0 | AL13: =IF(EXACT($A$16,$P13),$O13,0) -> #VALUE! | AM13: =IF(ISERR(AL13),0,AL13) -> 0 | AN13: =IF(EXACT($A$17,$P13),$O13,0) -> #VALUE! | AO13: =IF(ISERR(AN13),0,AN13) -> 0 | AP13: =IF(EXACT($A$18,$P13),$O13,0) -> #VALUE! | AQ13: =IF(ISERR(AP13),0,AP13) -> 0 | AR13: =IF(EXACT($A$19,$P13),$O13,0) -> #VALUE! | AS13: =IF(ISERR(AR13),0,AR13) -> 0 | AT13: =IF(EXACT($A$20,$P13),$O13,0) -> #VALUE! | AU13: =IF(ISERR(AT13),0,AT13) -> 0 | AV13: =IF(EXACT($A$21,$P13),$O13,0) -> #VALUE! | AW13: =IF(ISERR(AV13),0,AV13) -> 0 | AX13: =IF(EXACT($A$22,$P13),$O13,0) -> #VALUE! | AY13: =IF(ISERR(AX13),0,AX13) -> 0 | AZ13: =IF(EXACT($A$23,$P13),$O13,0) -> #VALUE! | BA13: =IF(ISERR(AZ13),0,AZ13) -> 0 | BB13: =IF(EXACT($A$24,$P13),$O13,0) -> #VALUE! | BC13: =IF(ISERR(BB13),0,BB13) -> 0 | BD13: =IF(EXACT($A$25,$P13),$O13,0) -> #VALUE! | BE13: =IF(ISERR(BD13),0,BD13) -> 0 | BF13: =IF(EXACT($A$26,$P13),$O13,0) -> #VALUE! | BG13: =IF(ISERR(BF13),0,BF13) -> 0 | BH13: =IF(EXACT($A$27,$P13),$O13,0) -> #VALUE! | BI13: =IF(ISERR(BH13),0,BH13) -> 0 | BJ13: =IF(EXACT($A$28,$P13),$O13,0) -> #VALUE! | BK13: =IF(ISERR(BJ13),0,BJ13) -> 0 | BL13: =IF(EXACT($A$29,$P13),$O13,0) -> #VALUE! | BM13: =IF(ISERR(BL13),0,BL13) -> 0 | BN13: =IF(EXACT($A$30,$P13),$O13,0) -> #VALUE! | BO13: =IF(ISERR(BN13),0,BN13) -> 0
E14: =IF(AND(C14=0,D14=0)," ",+C14*D14) | F14: =IF(AND(C14=0,D14=0)," ",+AI32) | G14: =IF(AND(C14=0,D14=0)," ",+E14+F14) | J14: =IF(AND(C14=0,D14=0)," ",+G14*I14) | M14: =IF(AND(C14=0,D14=0)," ",+K37) | N14: =IF(AND(C14=0,D14=0)," ",O37) | O14: =IF(AND(C14=0,D14=0)," ",+G14*(1-(N14/100))) | R14: =K14+0.25*(1-(1-$M$6/M14)^2.67) -> #DIV/0! | S14: =($M$4+K14*$M$6)/$M$6 -> 0.125 | T14: =($M$4/($M$4+$M$6*K14))*(0.56/$M$5*S14^1.667*L14^0.5*$M$6^2.667)/J14 -> #DIV/0! | U14: =K14+($M$4/$M$6)*T14 -> #DIV/0! | V14: =IF(B14>=15,0.54*J14^0.42*L14^0.3*(1/($M$5*U14))^0.6,W14) -> #DIV/0! | W14: =0.58*J14^0.42*L14^0.3*(1/($M$5*U14))^0.6 -> #DIV/0! | X14: =IF($M$4=0,0.6*J14^0.42*L14^0.3*(1/($M$5*U14))^0.6,V14) -> #DIV/0! | Y14: =IF(B14>X14,1,1-(1-B14/X14)^1.8) -> #DIV/0! | AB14: =IF(EXACT($A$11,$P14),$O14,0) -> #VALUE! | AC14: =IF(ISERR(AB14),0,AB14) -> 0 | AD14: =IF(EXACT($A$12,$P14),$O14,0) -> #VALUE! | AE14: =IF(ISERR(AD14),0,AD14) -> 0 | AF14: =IF(EXACT($A$13,$P14),$O14,0) -> #VALUE! | AG14: =IF(ISERR(AF14),0,AF14) -> 0 | AH14: =IF(EXACT($A$14,$P14),$O14,0) -> #VALUE! | AI14: =IF(ISERR(AH14),0,AH14) -> 0 | AJ14: =IF(EXACT($A$15,$P14),$O14,0) -> #VALUE! | AK14: =IF(ISERR(AJ14),0,AJ14) -> 0 | AL14: =IF(EXACT($A$16,$P14),$O14,0) -> #VALUE! | AM14: =IF(ISERR(AL14),0,AL14) -> 0 | AN14: =IF(EXACT($A$17,$P14),$O14,0) -> #VALUE! | AO14: =IF(ISERR(AN14),0,AN14) -> 0 | AP14: =IF(EXACT($A$18,$P14),$O14,0) -> #VALUE! | AQ14: =IF(ISERR(AP14),0,AP14) -> 0 | AR14: =IF(EXACT($A$19,$P14),$O14,0) -> #VALUE! | AS14: =IF(ISERR(AR14),0,AR14) -> 0 | AT14: =IF(EXACT($A$20,$P14),$O14,0) -> #VALUE! | AU14: =IF(ISERR(AT14),0,AT14) -> 0 | AV14: =IF(EXACT($A$21,$P14),$O14,0) -> #VALUE! | AW14: =IF(ISERR(AV14),0,AV14) -> 0 | AX14: =IF(EXACT($A$22,$P14),$O14,0) -> #VALUE! | AY14: =IF(ISERR(AX14),0,AX14) -> 0 | AZ14: =IF(EXACT($A$23,$P14),$O14,0) -> #VALUE! | BA14: =IF(ISERR(AZ14),0,AZ14) -> 0 | BB14: =IF(EXACT($A$24,$P14),$O14,0) -> #VALUE! | BC14: =IF(ISERR(BB14),0,BB14) -> 0 | BD14: =IF(EXACT($A$25,$P14),$O14,0) -> #VALUE! | BE14: =IF(ISERR(BD14),0,BD14) -> 0 | BF14: =IF(EXACT($A$26,$P14),$O14,0) -> #VALUE! | BG14: =IF(ISERR(BF14),0,BF14) -> 0 | BH14: =IF(EXACT($A$27,$P14),$O14,0) -> #VALUE! | BI14: =IF(ISERR(BH14),0,BH14) -> 0 | BJ14: =IF(EXACT($A$28,$P14),$O14,0) -> #VALUE! | BK14: =IF(ISERR(BJ14),0,BJ14) -> 0 | BL14: =IF(EXACT($A$29,$P14),$O14,0) -> #VALUE! | BM14: =IF(ISERR(BL14),0,BL14) -> 0 | BN14: =IF(EXACT($A$30,$P14),$O14,0) -> #VALUE! | BO14: =IF(ISERR(BN14),0,BN14) -> 0
E15: =IF(AND(C15=0,D15=0)," ",+C15*D15) | F15: =IF(AND(C15=0,D15=0)," ",+AK32) | G15: =IF(AND(C15=0,D15=0)," ",+E15+F15) | J15: =IF(AND(C15=0,D15=0)," ",+G15*I15) | M15: =IF(AND(C15=0,D15=0)," ",+K38) | N15: =IF(AND(C15=0,D15=0)," ",O38) | O15: =IF(AND(C15=0,D15=0)," ",+G15*(1-(N15/100))) | R15: =K15+0.25*(1-(1-$M$6/M15)^2.67) -> #DIV/0! | S15: =($M$4+K15*$M$6)/$M$6 -> 0.125 | T15: =($M$4/($M$4+$M$6*K15))*(0.56/$M$5*S15^1.667*L15^0.5*$M$6^2.667)/J15 -> #DIV/0! | U15: =K15+($M$4/$M$6)*T15 -> #DIV/0! | V15: =IF(B15>=15,0.54*J15^0.42*L15^0.3*(1/($M$5*U15))^0.6,W15) -> #DIV/0! | W15: =0.58*J15^0.42*L15^0.3*(1/($M$5*U15))^0.6 -> #DIV/0! | X15: =IF($M$4=0,0.6*J15^0.42*L15^0.3*(1/($M$5*U15))^0.6,V15) -> #DIV/0! | Y15: =IF(B15>X15,1,1-(1-B15/X15)^1.8) -> #DIV/0! | AB15: =IF(EXACT($A$11,$P15),$O15,0) -> #VALUE! | AC15: =IF(ISERR(AB15),0,AB15) -> 0 | AD15: =IF(EXACT($A$12,$P15),$O15,0) -> #VALUE! | AE15: =IF(ISERR(AD15),0,AD15) -> 0 | AF15: =IF(EXACT($A$13,$P15),$O15,0) -> #VALUE! | AG15: =IF(ISERR(AF15),0,AF15) -> 0 | AH15: =IF(EXACT($A$14,$P15),$O15,0) -> #VALUE! | AI15: =IF(ISERR(AH15),0,AH15) -> 0 | AJ15: =IF(EXACT($A$15,$P15),$O15,0) -> #VALUE! | AK15: =IF(ISERR(AJ15),0,AJ15) -> 0 | AL15: =IF(EXACT($A$16,$P15),$O15,0) -> #VALUE! | AM15: =IF(ISERR(AL15),0,AL15) -> 0 | AN15: =IF(EXACT($A$17,$P15),$O15,0) -> #VALUE! | AO15: =IF(ISERR(AN15),0,AN15) -> 0 | AP15: =IF(EXACT($A$18,$P15),$O15,0) -> #VALUE! | AQ15: =IF(ISERR(AP15),0,AP15) -> 0 | AR15: =IF(EXACT($A$19,$P15),$O15,0) -> #VALUE! | AS15: =IF(ISERR(AR15),0,AR15) -> 0 | AT15: =IF(EXACT($A$20,$P15),$O15,0) -> #VALUE! | AU15: =IF(ISERR(AT15),0,AT15) -> 0 | AV15: =IF(EXACT($A$21,$P15),$O15,0) -> #VALUE! | AW15: =IF(ISERR(AV15),0,AV15) -> 0 | AX15: =IF(EXACT($A$22,$P15),$O15,0) -> #VALUE! | AY15: =IF(ISERR(AX15),0,AX15) -> 0 | AZ15: =IF(EXACT($A$23,$P15),$O15,0) -> #VALUE! | BA15: =IF(ISERR(AZ15),0,AZ15) -> 0 | BB15: =IF(EXACT($A$24,$P15),$O15,0) -> #VALUE! | BC15: =IF(ISERR(BB15),0,BB15) -> 0 | BD15: =IF(EXACT($A$25,$P15),$O15,0) -> #VALUE! | BE15: =IF(ISERR(BD15),0,BD15) -> 0 | BF15: =IF(EXACT($A$26,$P15),$O15,0) -> #VALUE! | BG15: =IF(ISERR(BF15),0,BF15) -> 0 | BH15: =IF(EXACT($A$27,$P15),$O15,0) -> #VALUE! | BI15: =IF(ISERR(BH15),0,BH15) -> 0 | BJ15: =IF(EXACT($A$28,$P15),$O15,0) -> #VALUE! | BK15: =IF(ISERR(BJ15),0,BJ15) -> 0 | BL15: =IF(EXACT($A$29,$P15),$O15,0) -> #VALUE! | BM15: =IF(ISERR(BL15),0,BL15) -> 0 | BN15: =IF(EXACT($A$30,$P15),$O15,0) -> #VALUE! | BO15: =IF(ISERR(BN15),0,BN15) -> 0
E16: =IF(AND(C16=0,D16=0)," ",+C16*D16) | F16: =IF(AND(C16=0,D16=0)," ",+AM32) | G16: =IF(AND(C16=0,D16=0)," ",+E16+F16) | J16: =IF(AND(C16=0,D16=0)," ",+G16*I16) | M16: =IF(AND(C16=0,D16=0)," ",+K39) | N16: =IF(AND(C16=0,D16=0)," ",O39) | O16: =IF(AND(C16=0,D16=0)," ",+G16*(1-(N16/100))) | R16: =K16+0.25*(1-(1-$M$6/M16)^2.67) -> #DIV/0! | S16: =($M$4+K16*$M$6)/$M$6 -> 0.125 | T16: =($M$4/($M$4+$M$6*K16))*(0.56/$M$5*S16^1.667*L16^0.5*$M$6^2.667)/J16 -> #DIV/0! | U16: =K16+($M$4/$M$6)*T16 -> #DIV/0! | V16: =IF(B16>=15,0.54*J16^0.42*L16^0.3*(1/($M$5*U16))^0.6,W16) -> #DIV/0! | W16: =0.58*J16^0.42*L16^0.3*(1/($M$5*U16))^0.6 -> #DIV/0! | X16: =IF($M$4=0,0.6*J16^0.42*L16^0.3*(1/($M$5*U16))^0.6,V16) -> #DIV/0! | Y16: =IF(B16>X16,1,1-(1-B16/X16)^1.8) -> #DIV/0! | AB16: =IF(EXACT($A$11,$P16),$O16,0) -> #VALUE! | AC16: =IF(ISERR(AB16),0,AB16) -> 0 | AD16: =IF(EXACT($A$12,$P16),$O16,0) -> #VALUE! | AE16: =IF(ISERR(AD16),0,AD16) -> 0 | AF16: =IF(EXACT($A$13,$P16),$O16,0) -> #VALUE! | AG16: =IF(ISERR(AF16),0,AF16) -> 0 | AH16: =IF(EXACT($A$14,$P16),$O16,0) -> #VALUE! | AI16: =IF(ISERR(AH16),0,AH16) -> 0 | AJ16: =IF(EXACT($A$15,$P16),$O16,0) -> #VALUE! | AK16: =IF(ISERR(AJ16),0,AJ16) -> 0 | AL16: =IF(EXACT($A$16,$P16),$O16,0) -> #VALUE! | AM16: =IF(ISERR(AL16),0,AL16) -> 0 | AN16: =IF(EXACT($A$17,$P16),$O16,0) -> #VALUE! | AO16: =IF(ISERR(AN16),0,AN16) -> 0 | AP16: =IF(EXACT($A$18,$P16),$O16,0) -> #VALUE! | AQ16: =IF(ISERR(AP16),0,AP16) -> 0 | AR16: =IF(EXACT($A$19,$P16),$O16,0) -> #VALUE! | AS16: =IF(ISERR(AR16),0,AR16) -> 0 | AT16: =IF(EXACT($A$20,$P16),$O16,0) -> #VALUE! | AU16: =IF(ISERR(AT16),0,AT16) -> 0 | AV16: =IF(EXACT($A$21,$P16),$O16,0) -> #VALUE! | AW16: =IF(ISERR(AV16),0,AV16) -> 0 | AX16: =IF(EXACT($A$22,$P16),$O16,0) -> #VALUE! | AY16: =IF(ISERR(AX16),0,AX16) -> 0 | AZ16: =IF(EXACT($A$23,$P16),$O16,0) -> #VALUE! | BA16: =IF(ISERR(AZ16),0,AZ16) -> 0 | BB16: =IF(EXACT($A$24,$P16),$O16,0) -> #VALUE! | BC16: =IF(ISERR(BB16),0,BB16) -> 0 | BD16: =IF(EXACT($A$25,$P16),$O16,0) -> #VALUE! | BE16: =IF(ISERR(BD16),0,BD16) -> 0 | BF16: =IF(EXACT($A$26,$P16),$O16,0) -> #VALUE! | BG16: =IF(ISERR(BF16),0,BF16) -> 0 | BH16: =IF(EXACT($A$27,$P16),$O16,0) -> #VALUE! | BI16: =IF(ISERR(BH16),0,BH16) -> 0 | BJ16: =IF(EXACT($A$28,$P16),$O16,0) -> #VALUE! | BK16: =IF(ISERR(BJ16),0,BJ16) -> 0 | BL16: =IF(EXACT($A$29,$P16),$O16,0) -> #VALUE! | BM16: =IF(ISERR(BL16),0,BL16) -> 0 | BN16: =IF(EXACT($A$30,$P16),$O16,0) -> #VALUE! | BO16: =IF(ISERR(BN16),0,BN16) -> 0
E17: =IF(AND(C17=0,D17=0)," ",+C17*D17) | F17: =IF(AND(C17=0,D17=0)," ",+AO32) | G17: =IF(AND(C17=0,D17=0)," ",+E17+F17) | J17: =IF(AND(C17=0,D17=0)," ",+G17*I17) | M17: =IF(AND(C17=0,D17=0)," ",+K40) | N17: =IF(AND(C17=0,D17=0)," ",O40) | O17: =IF(AND(C17=0,D17=0)," ",+G17*(1-(N17/100))) | R17: =K17+0.25*(1-(1-$M$6/M17)^2.67) -> #DIV/0! | S17: =($M$4+K17*$M$6)/$M$6 -> 0.125 | T17: =($M$4/($M$4+$M$6*K17))*(0.56/$M$5*S17^1.667*L17^0.5*$M$6^2.667)/J17 -> #DIV/0! | U17: =K17+($M$4/$M$6)*T17 -> #DIV/0! | V17: =IF(B17>=15,0.54*J17^0.42*L17^0.3*(1/($M$5*U17))^0.6,W17) -> #DIV/0! | W17: =0.58*J17^0.42*L17^0.3*(1/($M$5*U17))^0.6 -> #DIV/0! | X17: =IF($M$4=0,0.6*J17^0.42*L17^0.3*(1/($M$5*U17))^0.6,V17) -> #DIV/0! | Y17: =IF(B17>X17,1,1-(1-B17/X17)^1.8) -> #DIV/0! | AB17: =IF(EXACT($A$11,$P17),$O17,0) -> #VALUE! | AC17: =IF(ISERR(AB17),0,AB17) -> 0 | AD17: =IF(EXACT($A$12,$P17),$O17,0) -> #VALUE! | AE17: =IF(ISERR(AD17),0,AD17) -> 0 | AF17: =IF(EXACT($A$13,$P17),$O17,0) -> #VALUE! | AG17: =IF(ISERR(AF17),0,AF17) -> 0 | AH17: =IF(EXACT($A$14,$P17),$O17,0) -> #VALUE! | AI17: =IF(ISERR(AH17),0,AH17) -> 0 | AJ17: =IF(EXACT($A$15,$P17),$O17,0) -> #VALUE! | AK17: =IF(ISERR(AJ17),0,AJ17) -> 0 | AL17: =IF(EXACT($A$16,$P17),$O17,0) -> #VALUE! | AM17: =IF(ISERR(AL17),0,AL17) -> 0 | AN17: =IF(EXACT($A$17,$P17),$O17,0) -> #VALUE! | AO17: =IF(ISERR(AN17),0,AN17) -> 0 | AP17: =IF(EXACT($A$18,$P17),$O17,0) -> #VALUE! | AQ17: =IF(ISERR(AP17),0,AP17) -> 0 | AR17: =IF(EXACT($A$19,$P17),$O17,0) -> #VALUE! | AS17: =IF(ISERR(AR17),0,AR17) -> 0 | AT17: =IF(EXACT($A$20,$P17),$O17,0) -> #VALUE! | AU17: =IF(ISERR(AT17),0,AT17) -> 0 | AV17: =IF(EXACT($A$21,$P17),$O17,0) -> #VALUE! | AW17: =IF(ISERR(AV17),0,AV17) -> 0 | AX17: =IF(EXACT($A$22,$P17),$O17,0) -> #VALUE! | AY17: =IF(ISERR(AX17),0,AX17) -> 0 | AZ17: =IF(EXACT($A$23,$P17),$O17,0) -> #VALUE! | BA17: =IF(ISERR(AZ17),0,AZ17) -> 0 | BB17: =IF(EXACT($A$24,$P17),$O17,0) -> #VALUE! | BC17: =IF(ISERR(BB17),0,BB17) -> 0 | BD17: =IF(EXACT($A$25,$P17),$O17,0) -> #VALUE! | BE17: =IF(ISERR(BD17),0,BD17) -> 0 | BF17: =IF(EXACT($A$26,$P17),$O17,0) -> #VALUE! | BG17: =IF(ISERR(BF17),0,BF17) -> 0 | BH17: =IF(EXACT($A$27,$P17),$O17,0) -> #VALUE! | BI17: =IF(ISERR(BH17),0,BH17) -> 0 | BJ17: =IF(EXACT($A$28,$P17),$O17,0) -> #VALUE! | BK17: =IF(ISERR(BJ17),0,BJ17) -> 0 | BL17: =IF(EXACT($A$29,$P17),$O17,0) -> #VALUE! | BM17: =IF(ISERR(BL17),0,BL17) -> 0 | BN17: =IF(EXACT($A$30,$P17),$O17,0) -> #VALUE! | BO17: =IF(ISERR(BN17),0,BN17) -> 0
E18: =IF(AND(C18=0,D18=0)," ",+C18*D18) | F18: =IF(AND(C18=0,D18=0)," ",+AQ32) | G18: =IF(AND(C18=0,D18=0)," ",+E18+F18) | J18: =IF(AND(C18=0,D18=0)," ",+G18*I18) | M18: =IF(AND(C18=0,D18=0)," ",+K41) | N18: =IF(AND(C18=0,D18=0)," ",O41) | O18: =IF(AND(C18=0,D18=0)," ",+G18*(1-(N18/100))) | R18: =K18+0.25*(1-(1-$M$6/M18)^2.67) -> #DIV/0! | S18: =($M$4+K18*$M$6)/$M$6 -> 0.125 | T18: =($M$4/($M$4+$M$6*K18))*(0.56/$M$5*S18^1.667*L18^0.5*$M$6^2.667)/J18 -> #DIV/0! | U18: =K18+($M$4/$M$6)*T18 -> #DIV/0! | V18: =IF(B18>=15,0.54*J18^0.42*L18^0.3*(1/($M$5*U18))^0.6,W18) -> #DIV/0! | W18: =0.58*J18^0.42*L18^0.3*(1/($M$5*U18))^0.6 -> #DIV/0! | X18: =IF($M$4=0,0.6*J18^0.42*L18^0.3*(1/($M$5*U18))^0.6,V18) -> #DIV/0! | Y18: =IF(B18>X18,1,1-(1-B18/X18)^1.8) -> #DIV/0! | AB18: =IF(EXACT($A$11,$P18),$O18,0) -> #VALUE! | AC18: =IF(ISERR(AB18),0,AB18) -> 0 | AD18: =IF(EXACT($A$12,$P18),$O18,0) -> #VALUE! | AE18: =IF(ISERR(AD18),0,AD18) -> 0 | AF18: =IF(EXACT($A$13,$P18),$O18,0) -> #VALUE! | AG18: =IF(ISERR(AF18),0,AF18) -> 0 | AH18: =IF(EXACT($A$14,$P18),$O18,0) -> #VALUE! | AI18: =IF(ISERR(AH18),0,AH18) -> 0 | AJ18: =IF(EXACT($A$15,$P18),$O18,0) -> #VALUE! | AK18: =IF(ISERR(AJ18),0,AJ18) -> 0 | AL18: =IF(EXACT($A$16,$P18),$O18,0) -> #VALUE! | AM18: =IF(ISERR(AL18),0,AL18) -> 0 | AN18: =IF(EXACT($A$17,$P18),$O18,0) -> #VALUE! | AO18: =IF(ISERR(AN18),0,AN18) -> 0 | AP18: =IF(EXACT($A$18,$P18),$O18,0) -> #VALUE! | AQ18: =IF(ISERR(AP18),0,AP18) -> 0 | AR18: =IF(EXACT($A$19,$P18),$O18,0) -> #VALUE! | AS18: =IF(ISERR(AR18),0,AR18) -> 0 | AT18: =IF(EXACT($A$20,$P18),$O18,0) -> #VALUE! | AU18: =IF(ISERR(AT18),0,AT18) -> 0 | AV18: =IF(EXACT($A$21,$P18),$O18,0) -> #VALUE! | AW18: =IF(ISERR(AV18),0,AV18) -> 0 | AX18: =IF(EXACT($A$22,$P18),$O18,0) -> #VALUE! | AY18: =IF(ISERR(AX18),0,AX18) -> 0 | AZ18: =IF(EXACT($A$23,$P18),$O18,0) -> #VALUE! | BA18: =IF(ISERR(AZ18),0,AZ18) -> 0 | BB18: =IF(EXACT($A$24,$P18),$O18,0) -> #VALUE! | BC18: =IF(ISERR(BB18),0,BB18) -> 0 | BD18: =IF(EXACT($A$25,$P18),$O18,0) -> #VALUE! | BE18: =IF(ISERR(BD18),0,BD18) -> 0 | BF18: =IF(EXACT($A$26,$P18),$O18,0) -> #VALUE! | BG18: =IF(ISERR(BF18),0,BF18) -> 0 | BH18: =IF(EXACT($A$27,$P18),$O18,0) -> #VALUE! | BI18: =IF(ISERR(BH18),0,BH18) -> 0 | BJ18: =IF(EXACT($A$28,$P18),$O18,0) -> #VALUE! | BK18: =IF(ISERR(BJ18),0,BJ18) -> 0 | BL18: =IF(EXACT($A$29,$P18),$O18,0) -> #VALUE! | BM18: =IF(ISERR(BL18),0,BL18) -> 0 | BN18: =IF(EXACT($A$30,$P18),$O18,0) -> #VALUE! | BO18: =IF(ISERR(BN18),0,BN18) -> 0
E19: =IF(AND(C19=0,D19=0)," ",+C19*D19) | F19: =IF(AND(C19=0,D19=0)," ",+AS32) | G19: =IF(AND(C19=0,D19=0)," ",+E19+F19) | J19: =IF(AND(C19=0,D19=0)," ",+G19*I19) | M19: =IF(AND(C19=0,D19=0)," ",+K42) | N19: =IF(AND(C19=0,D19=0)," ",O42) | O19: =IF(AND(C19=0,D19=0)," ",+G19*(1-(N19/100))) | R19: =K19+0.25*(1-(1-$M$6/M19)^2.67) -> #DIV/0! | S19: =($M$4+K19*$M$6)/$M$6 -> 0.125 | T19: =($M$4/($M$4+$M$6*K19))*(0.56/$M$5*S19^1.667*L19^0.5*$M$6^2.667)/J19 -> #DIV/0! | U19: =K19+($M$4/$M$6)*T19 -> #DIV/0! | V19: =IF(B19>=15,0.54*J19^0.42*L19^0.3*(1/($M$5*U19))^0.6,W19) -> #DIV/0! | W19: =0.58*J19^0.42*L19^0.3*(1/($M$5*U19))^0.6 -> #DIV/0! | X19: =IF($M$4=0,0.6*J19^0.42*L19^0.3*(1/($M$5*U19))^0.6,V19) -> #DIV/0! | Y19: =IF(B19>X19,1,1-(1-B19/X19)^1.8) -> #DIV/0! | AB19: =IF(EXACT($A$11,$P19),$O19,0) -> #VALUE! | AC19: =IF(ISERR(AB19),0,AB19) -> 0 | AD19: =IF(EXACT($A$12,$P19),$O19,0) -> #VALUE! | AE19: =IF(ISERR(AD19),0,AD19) -> 0 | AF19: =IF(EXACT($A$13,$P19),$O19,0) -> #VALUE! | AG19: =IF(ISERR(AF19),0,AF19) -> 0 | AH19: =IF(EXACT($A$14,$P19),$O19,0) -> #VALUE! | AI19: =IF(ISERR(AH19),0,AH19) -> 0 | AJ19: =IF(EXACT($A$15,$P19),$O19,0) -> #VALUE! | AK19: =IF(ISERR(AJ19),0,AJ19) -> 0 | AL19: =IF(EXACT($A$16,$P19),$O19,0) -> #VALUE! | AM19: =IF(ISERR(AL19),0,AL19) -> 0 | AN19: =IF(EXACT($A$17,$P19),$O19,0) -> #VALUE! | AO19: =IF(ISERR(AN19),0,AN19) -> 0 | AP19: =IF(EXACT($A$18,$P19),$O19,0) -> #VALUE! | AQ19: =IF(ISERR(AP19),0,AP19) -> 0 | AR19: =IF(EXACT($A$19,$P19),$O19,0) -> #VALUE! | AS19: =IF(ISERR(AR19),0,AR19) -> 0 | AT19: =IF(EXACT($A$20,$P19),$O19,0) -> #VALUE! | AU19: =IF(ISERR(AT19),0,AT19) -> 0 | AV19: =IF(EXACT($A$21,$P19),$O19,0) -> #VALUE! | AW19: =IF(ISERR(AV19),0,AV19) -> 0 | AX19: =IF(EXACT($A$22,$P19),$O19,0) -> #VALUE! | AY19: =IF(ISERR(AX19),0,AX19) -> 0 | AZ19: =IF(EXACT($A$23,$P19),$O19,0) -> #VALUE! | BA19: =IF(ISERR(AZ19),0,AZ19) -> 0 | BB19: =IF(EXACT($A$24,$P19),$O19,0) -> #VALUE! | BC19: =IF(ISERR(BB19),0,BB19) -> 0 | BD19: =IF(EXACT($A$25,$P19),$O19,0) -> #VALUE! | BE19: =IF(ISERR(BD19),0,BD19) -> 0 | BF19: =IF(EXACT($A$26,$P19),$O19,0) -> #VALUE! | BG19: =IF(ISERR(BF19),0,BF19) -> 0 | BH19: =IF(EXACT($A$27,$P19),$O19,0) -> #VALUE! | BI19: =IF(ISERR(BH19),0,BH19) -> 0 | BJ19: =IF(EXACT($A$28,$P19),$O19,0) -> #VALUE! | BK19: =IF(ISERR(BJ19),0,BJ19) -> 0 | BL19: =IF(EXACT($A$29,$P19),$O19,0) -> #VALUE! | BM19: =IF(ISERR(BL19),0,BL19) -> 0 | BN19: =IF(EXACT($A$30,$P19),$O19,0) -> #VALUE! | BO19: =IF(ISERR(BN19),0,BN19) -> 0
E20: =IF(AND(C20=0,D20=0)," ",+C20*D20) | F20: =IF(AND(C20=0,D20=0)," ",AU32) | G20: =IF(AND(C20=0,D20=0)," ",+E20+F20) | J20: =IF(AND(C20=0,D20=0)," ",+G20*I20) | M20: =IF(AND(C20=0,D20=0)," ",+K43) | N20: =IF(AND(C20=0,D20=0)," ",O43) | O20: =IF(AND(C20=0,D20=0)," ",+G20*(1-(N20/100))) | R20: =K20+0.25*(1-(1-$M$6/M20)^2.67) -> #DIV/0! | S20: =($M$4+K20*$M$6)/$M$6 -> 0.125 | T20: =($M$4/($M$4+$M$6*K20))*(0.56/$M$5*S20^1.667*L20^0.5*$M$6^2.667)/J20 -> #DIV/0! | U20: =K20+($M$4/$M$6)*T20 -> #DIV/0! | V20: =IF(B20>=15,0.54*J20^0.42*L20^0.3*(1/($M$5*U20))^0.6,W20) -> #DIV/0! | W20: =0.58*J20^0.42*L20^0.3*(1/($M$5*U20))^0.6 -> #DIV/0! | X20: =IF($M$4=0,0.6*J20^0.42*L20^0.3*(1/($M$5*U20))^0.6,V20) -> #DIV/0! | Y20: =IF(B20>X20,1,1-(1-B20/X20)^1.8) -> #DIV/0! | AB20: =IF(EXACT($A$11,$P20),$O20,0) -> #VALUE! | AC20: =IF(ISERR(AB20),0,AB20) -> 0 | AD20: =IF(EXACT($A$12,$P20),$O20,0) -> #VALUE! | AE20: =IF(ISERR(AD20),0,AD20) -> 0 | AF20: =IF(EXACT($A$13,$P20),$O20,0) -> #VALUE! | AG20: =IF(ISERR(AF20),0,AF20) -> 0 | AH20: =IF(EXACT($A$14,$P20),$O20,0) -> #VALUE! | AI20: =IF(ISERR(AH20),0,AH20) -> 0 | AJ20: =IF(EXACT($A$15,$P20),$O20,0) -> #VALUE! | AK20: =IF(ISERR(AJ20),0,AJ20) -> 0 | AL20: =IF(EXACT($A$16,$P20),$O20,0) -> #VALUE! | AM20: =IF(ISERR(AL20),0,AL20) -> 0 | AN20: =IF(EXACT($A$17,$P20),$O20,0) -> #VALUE! | AO20: =IF(ISERR(AN20),0,AN20) -> 0 | AP20: =IF(EXACT($A$18,$P20),$O20,0) -> #VALUE! | AQ20: =IF(ISERR(AP20),0,AP20) -> 0 | AR20: =IF(EXACT($A$19,$P20),$O20,0) -> #VALUE! | AS20: =IF(ISERR(AR20),0,AR20) -> 0 | AT20: =IF(EXACT($A$20,$P20),$O20,0) -> #VALUE! | AU20: =IF(ISERR(AT20),0,AT20) -> 0 | AV20: =IF(EXACT($A$21,$P20),$O20,0) -> #VALUE! | AW20: =IF(ISERR(AV20),0,AV20) -> 0 | AX20: =IF(EXACT($A$22,$P20),$O20,0) -> #VALUE! | AY20: =IF(ISERR(AX20),0,AX20) -> 0 | AZ20: =IF(EXACT($A$23,$P20),$O20,0) -> #VALUE! | BA20: =IF(ISERR(AZ20),0,AZ20) -> 0 | BB20: =IF(EXACT($A$24,$P20),$O20,0) -> #VALUE! | BC20: =IF(ISERR(BB20),0,BB20) -> 0 | BD20: =IF(EXACT($A$25,$P20),$O20,0) -> #VALUE! | BE20: =IF(ISERR(BD20),0,BD20) -> 0 | BF20: =IF(EXACT($A$26,$P20),$O20,0) -> #VALUE! | BG20: =IF(ISERR(BF20),0,BF20) -> 0 | BH20: =IF(EXACT($A$27,$P20),$O20,0) -> #VALUE! | BI20: =IF(ISERR(BH20),0,BH20) -> 0 | BJ20: =IF(EXACT($A$28,$P20),$O20,0) -> #VALUE! | BK20: =IF(ISERR(BJ20),0,BJ20) -> 0 | BL20: =IF(EXACT($A$29,$P20),$O20,0) -> #VALUE! | BM20: =IF(ISERR(BL20),0,BL20) -> 0 | BN20: =IF(EXACT($A$30,$P20),$O20,0) -> #VALUE! | BO20: =IF(ISERR(BN20),0,BN20) -> 0
E21: =IF(AND(C21=0,D21=0)," ",+C21*D21) | F21: =IF(AND(C21=0,D21=0)," ",AW32) | G21: =IF(AND(C21=0,D21=0)," ",+E21+F21) | J21: =IF(AND(C21=0,D21=0)," ",+G21*I21) | M21: =IF(AND(C21=0,D21=0)," ",+K44) | N21: =IF(AND(C21=0,D21=0)," ",O44) | O21: =IF(AND(C21=0,D21=0)," ",+G21*(1-(N21/100))) | R21: =K21+0.25*(1-(1-$M$6/M21)^2.67) -> #DIV/0! | S21: =($M$4+K21*$M$6)/$M$6 -> 0.125 | T21: =($M$4/($M$4+$M$6*K21))*(0.56/$M$5*S21^1.667*L21^0.5*$M$6^2.667)/J21 -> #DIV/0! | U21: =K21+($M$4/$M$6)*T21 -> #DIV/0! | V21: =IF(B21>=15,0.54*J21^0.42*L21^0.3*(1/($M$5*U21))^0.6,W21) -> #DIV/0! | W21: =0.58*J21^0.42*L21^0.3*(1/($M$5*U21))^0.6 -> #DIV/0! | X21: =IF($M$4=0,0.6*J21^0.42*L21^0.3*(1/($M$5*U21))^0.6,V21) -> #DIV/0! | Y21: =IF(B21>X21,1,1-(1-B21/X21)^1.8) -> #DIV/0! | AB21: =IF(EXACT($A$11,$P21),$O21,0) -> #VALUE! | AC21: =IF(ISERR(AB21),0,AB21) -> 0 | AD21: =IF(EXACT($A$12,$P21),$O21,0) -> #VALUE! | AE21: =IF(ISERR(AD21),0,AD21) -> 0 | AF21: =IF(EXACT($A$13,$P21),$O21,0) -> #VALUE! | AG21: =IF(ISERR(AF21),0,AF21) -> 0 | AH21: =IF(EXACT($A$14,$P21),$O21,0) -> #VALUE! | AI21: =IF(ISERR(AH21),0,AH21) -> 0 | AJ21: =IF(EXACT($A$15,$P21),$O21,0) -> #VALUE! | AK21: =IF(ISERR(AJ21),0,AJ21) -> 0 | AL21: =IF(EXACT($A$16,$P21),$O21,0) -> #VALUE! | AM21: =IF(ISERR(AL21),0,AL21) -> 0 | AN21: =IF(EXACT($A$17,$P21),$O21,0) -> #VALUE! | AO21: =IF(ISERR(AN21),0,AN21) -> 0 | AP21: =IF(EXACT($A$18,$P21),$O21,0) -> #VALUE! | AQ21: =IF(ISERR(AP21),0,AP21) -> 0 | AR21: =IF(EXACT($A$19,$P21),$O21,0) -> #VALUE! | AS21: =IF(ISERR(AR21),0,AR21) -> 0 | AT21: =IF(EXACT($A$20,$P21),$O21,0) -> #VALUE! | AU21: =IF(ISERR(AT21),0,AT21) -> 0 | AV21: =IF(EXACT($A$21,$P21),$O21,0) -> #VALUE! | AW21: =IF(ISERR(AV21),0,AV21) -> 0 | AX21: =IF(EXACT($A$22,$P21),$O21,0) -> #VALUE! | AY21: =IF(ISERR(AX21),0,AX21) -> 0 | AZ21: =IF(EXACT($A$23,$P21),$O21,0) -> #VALUE! | BA21: =IF(ISERR(AZ21),0,AZ21) -> 0 | BB21: =IF(EXACT($A$24,$P21),$O21,0) -> #VALUE! | BC21: =IF(ISERR(BB21),0,BB21) -> 0 | BD21: =IF(EXACT($A$25,$P21),$O21,0) -> #VALUE! | BE21: =IF(ISERR(BD21),0,BD21) -> 0 | BF21: =IF(EXACT($A$26,$P21),$O21,0) -> #VALUE! | BG21: =IF(ISERR(BF21),0,BF21) -> 0 | BH21: =IF(EXACT($A$27,$P21),$O21,0) -> #VALUE! | BI21: =IF(ISERR(BH21),0,BH21) -> 0 | BJ21: =IF(EXACT($A$28,$P21),$O21,0) -> #VALUE! | BK21: =IF(ISERR(BJ21),0,BJ21) -> 0 | BL21: =IF(EXACT($A$29,$P21),$O21,0) -> #VALUE! | BM21: =IF(ISERR(BL21),0,BL21) -> 0 | BN21: =IF(EXACT($A$30,$P21),$O21,0) -> #VALUE! | BO21: =IF(ISERR(BN21),0,BN21) -> 0
E22: =IF(AND(C22=0,D22=0)," ",+C22*D22) | F22: =IF(AND(C22=0,D22=0)," ",+AY32) | G22: =IF(AND(C22=0,D22=0)," ",+E22+F22) | J22: =IF(AND(C22=0,D22=0)," ",+G22*I22) | M22: =IF(AND(C22=0,D22=0)," ",+K45) | N22: =IF(AND(C22=0,D22=0)," ",O45) | O22: =IF(AND(C22=0,D22=0)," ",+G22*(1-(N22/100))) | R22: =K22+0.25*(1-(1-$M$6/M22)^2.67) -> #DIV/0! | S22: =($M$4+K22*$M$6)/$M$6 -> 0.125 | T22: =($M$4/($M$4+$M$6*K22))*(0.56/$M$5*S22^1.667*L22^0.5*$M$6^2.667)/J22 -> #DIV/0! | U22: =K22+($M$4/$M$6)*T22 -> #DIV/0! | V22: =IF(B22>=15,0.54*J22^0.42*L22^0.3*(1/($M$5*U22))^0.6,W22) -> #DIV/0! | W22: =0.58*J22^0.42*L22^0.3*(1/($M$5*U22))^0.6 -> #DIV/0! | X22: =IF($M$4=0,0.6*J22^0.42*L22^0.3*(1/($M$5*U22))^0.6,V22) -> #DIV/0! | Y22: =IF(B22>X22,1,1-(1-B22/X22)^1.8) -> #DIV/0! | AB22: =IF(EXACT($A$11,$P22),$O22,0) -> #VALUE! | AC22: =IF(ISERR(AB22),0,AB22) -> 0 | AD22: =IF(EXACT($A$12,$P22),$O22,0) -> #VALUE! | AE22: =IF(ISERR(AD22),0,AD22) -> 0 | AF22: =IF(EXACT($A$13,$P22),$O22,0) -> #VALUE! | AG22: =IF(ISERR(AF22),0,AF22) -> 0 | AH22: =IF(EXACT($A$14,$P22),$O22,0) -> #VALUE! | AI22: =IF(ISERR(AH22),0,AH22) -> 0 | AJ22: =IF(EXACT($A$15,$P22),$O22,0) -> #VALUE! | AK22: =IF(ISERR(AJ22),0,AJ22) -> 0 | AL22: =IF(EXACT($A$16,$P22),$O22,0) -> #VALUE! | AM22: =IF(ISERR(AL22),0,AL22) -> 0 | AN22: =IF(EXACT($A$17,$P22),$O22,0) -> #VALUE! | AO22: =IF(ISERR(AN22),0,AN22) -> 0 | AP22: =IF(EXACT($A$18,$P22),$O22,0) -> #VALUE! | AQ22: =IF(ISERR(AP22),0,AP22) -> 0 | AR22: =IF(EXACT($A$19,$P22),$O22,0) -> #VALUE! | AS22: =IF(ISERR(AR22),0,AR22) -> 0 | AT22: =IF(EXACT($A$20,$P22),$O22,0) -> #VALUE! | AU22: =IF(ISERR(AT22),0,AT22) -> 0 | AV22: =IF(EXACT($A$21,$P22),$O22,0) -> #VALUE! | AW22: =IF(ISERR(AV22),0,AV22) -> 0 | AX22: =IF(EXACT($A$22,$P22),$O22,0) -> #VALUE! | AY22: =IF(ISERR(AX22),0,AX22) -> 0 | AZ22: =IF(EXACT($A$23,$P22),$O22,0) -> #VALUE! | BA22: =IF(ISERR(AZ22),0,AZ22) -> 0 | BB22: =IF(EXACT($A$24,$P22),$O22,0) -> #VALUE! | BC22: =IF(ISERR(BB22),0,BB22) -> 0 | BD22: =IF(EXACT($A$25,$P22),$O22,0) -> #VALUE! | BE22: =IF(ISERR(BD22),0,BD22) -> 0 | BF22: =IF(EXACT($A$26,$P22),$O22,0) -> #VALUE! | BG22: =IF(ISERR(BF22),0,BF22) -> 0 | BH22: =IF(EXACT($A$27,$P22),$O22,0) -> #VALUE! | BI22: =IF(ISERR(BH22),0,BH22) -> 0 | BJ22: =IF(EXACT($A$28,$P22),$O22,0) -> #VALUE! | BK22: =IF(ISERR(BJ22),0,BJ22) -> 0 | BL22: =IF(EXACT($A$29,$P22),$O22,0) -> #VALUE! | BM22: =IF(ISERR(BL22),0,BL22) -> 0 | BN22: =IF(EXACT($A$30,$P22),$O22,0) -> #VALUE! | BO22: =IF(ISERR(BN22),0,BN22) -> 0
E23: =IF(AND(C23=0,D23=0)," ",+C23*D23) | F23: =IF(AND(C23=0,D23=0)," ",BA32) | G23: =IF(AND(C23=0,D23=0)," ",+E23+F23) | J23: =IF(AND(C23=0,D23=0)," ",+G23*I23) | M23: =IF(AND(C23=0,D23=0)," ",+K46) | N23: =IF(AND(C23=0,D23=0)," ",O46) | O23: =IF(AND(C23=0,D23=0)," ",+G23*(1-(N23/100))) | R23: =K23+0.25*(1-(1-$M$6/M23)^2.67) -> #DIV/0! | S23: =($M$4+K23*$M$6)/$M$6 -> 0.125 | T23: =($M$4/($M$4+$M$6*K23))*(0.56/$M$5*S23^1.667*L23^0.5*$M$6^2.667)/J23 -> #DIV/0! | U23: =K23+($M$4/$M$6)*T23 -> #DIV/0! | V23: =IF(B23>=15,0.54*J23^0.42*L23^0.3*(1/($M$5*U23))^0.6,W23) -> #DIV/0! | W23: =0.58*J23^0.42*L23^0.3*(1/($M$5*U23))^0.6 -> #DIV/0! | X23: =IF($M$4=0,0.6*J23^0.42*L23^0.3*(1/($M$5*U23))^0.6,V23) -> #DIV/0! | Y23: =IF(B23>X23,1,1-(1-B23/X23)^1.8) -> #DIV/0! | AB23: =IF(EXACT($A$11,$P23),$O23,0) -> #VALUE! | AC23: =IF(ISERR(AB23),0,AB23) -> 0 | AD23: =IF(EXACT($A$12,$P23),$O23,0) -> #VALUE! | AE23: =IF(ISERR(AD23),0,AD23) -> 0 | AF23: =IF(EXACT($A$13,$P23),$O23,0) -> #VALUE! | AG23: =IF(ISERR(AF23),0,AF23) -> 0 | AH23: =IF(EXACT($A$14,$P23),$O23,0) -> #VALUE! | AI23: =IF(ISERR(AH23),0,AH23) -> 0 | AJ23: =IF(EXACT($A$15,$P23),$O23,0) -> #VALUE! | AK23: =IF(ISERR(AJ23),0,AJ23) -> 0 | AL23: =IF(EXACT($A$16,$P23),$O23,0) -> #VALUE! | AM23: =IF(ISERR(AL23),0,AL23) -> 0 | AN23: =IF(EXACT($A$17,$P23),$O23,0) -> #VALUE! | AO23: =IF(ISERR(AN23),0,AN23) -> 0 | AP23: =IF(EXACT($A$18,$P23),$O23,0) -> #VALUE! | AQ23: =IF(ISERR(AP23),0,AP23) -> 0 | AR23: =IF(EXACT($A$19,$P23),$O23,0) -> #VALUE! | AS23: =IF(ISERR(AR23),0,AR23) -> 0 | AT23: =IF(EXACT($A$20,$P23),$O23,0) -> #VALUE! | AU23: =IF(ISERR(AT23),0,AT23) -> 0 | AV23: =IF(EXACT($A$21,$P23),$O23,0) -> #VALUE! | AW23: =IF(ISERR(AV23),0,AV23) -> 0 | AX23: =IF(EXACT($A$22,$P23),$O23,0) -> #VALUE! | AY23: =IF(ISERR(AX23),0,AX23) -> 0 | AZ23: =IF(EXACT($A$23,$P23),$O23,0) -> #VALUE! | BA23: =IF(ISERR(AZ23),0,AZ23) -> 0 | BB23: =IF(EXACT($A$24,$P23),$O23,0) -> #VALUE! | BC23: =IF(ISERR(BB23),0,BB23) -> 0 | BD23: =IF(EXACT($A$25,$P23),$O23,0) -> #VALUE! | BE23: =IF(ISERR(BD23),0,BD23) -> 0 | BF23: =IF(EXACT($A$26,$P23),$O23,0) -> #VALUE! | BG23: =IF(ISERR(BF23),0,BF23) -> 0 | BH23: =IF(EXACT($A$27,$P23),$O23,0) -> #VALUE! | BI23: =IF(ISERR(BH23),0,BH23) -> 0 | BJ23: =IF(EXACT($A$28,$P23),$O23,0) -> #VALUE! | BK23: =IF(ISERR(BJ23),0,BJ23) -> 0 | BL23: =IF(EXACT($A$29,$P23),$O23,0) -> #VALUE! | BM23: =IF(ISERR(BL23),0,BL23) -> 0 | BN23: =IF(EXACT($A$30,$P23),$O23,0) -> #VALUE! | BO23: =IF(ISERR(BN23),0,BN23) -> 0
E24: =IF(AND(C24=0,D24=0)," ",+C24*D24) | F24: =IF(AND(C24=0,D24=0)," ",+BC32) | G24: =IF(AND(C24=0,D24=0)," ",+E24+F24) | J24: =IF(AND(C24=0,D24=0)," ",+G24*I24) | M24: =IF(AND(C24=0,D24=0)," ",+K47) | N24: =IF(AND(C24=0,D24=0)," ",O47) | O24: =IF(AND(C24=0,D24=0)," ",+G24*(1-(N24/100))) | R24: =K24+0.25*(1-(1-$M$6/M24)^2.67) -> #DIV/0! | S24: =($M$4+K24*$M$6)/$M$6 -> 0.125 | T24: =($M$4/($M$4+$M$6*K24))*(0.56/$M$5*S24^1.667*L24^0.5*$M$6^2.667)/J24 -> #DIV/0! | U24: =K24+($M$4/$M$6)*T24 -> #DIV/0! | V24: =IF(B24>=15,0.54*J24^0.42*L24^0.3*(1/($M$5*U24))^0.6,W24) -> #DIV/0! | W24: =0.58*J24^0.42*L24^0.3*(1/($M$5*U24))^0.6 -> #DIV/0! | X24: =IF($M$4=0,0.6*J24^0.42*L24^0.3*(1/($M$5*U24))^0.6,V24) -> #DIV/0! | Y24: =IF(B24>X24,1,1-(1-B24/X24)^1.8) -> #DIV/0! | AB24: =IF(EXACT($A$11,$P24),$O24,0) -> #VALUE! | AC24: =IF(ISERR(AB24),0,AB24) -> 0 | AD24: =IF(EXACT($A$12,$P24),$O24,0) -> #VALUE! | AE24: =IF(ISERR(AD24),0,AD24) -> 0 | AF24: =IF(EXACT($A$13,$P24),$O24,0) -> #VALUE! | AG24: =IF(ISERR(AF24),0,AF24) -> 0 | AH24: =IF(EXACT($A$14,$P24),$O24,0) -> #VALUE! | AI24: =IF(ISERR(AH24),0,AH24) -> 0 | AJ24: =IF(EXACT($A$15,$P24),$O24,0) -> #VALUE! | AK24: =IF(ISERR(AJ24),0,AJ24) -> 0 | AL24: =IF(EXACT($A$16,$P24),$O24,0) -> #VALUE! | AM24: =IF(ISERR(AL24),0,AL24) -> 0 | AN24: =IF(EXACT($A$17,$P24),$O24,0) -> #VALUE! | AO24: =IF(ISERR(AN24),0,AN24) -> 0 | AP24: =IF(EXACT($A$18,$P24),$O24,0) -> #VALUE! | AQ24: =IF(ISERR(AP24),0,AP24) -> 0 | AR24: =IF(EXACT($A$19,$P24),$O24,0) -> #VALUE! | AS24: =IF(ISERR(AR24),0,AR24) -> 0 | AT24: =IF(EXACT($A$20,$P24),$O24,0) -> #VALUE! | AU24: =IF(ISERR(AT24),0,AT24) -> 0 | AV24: =IF(EXACT($A$21,$P24),$O24,0) -> #VALUE! | AW24: =IF(ISERR(AV24),0,AV24) -> 0 | AX24: =IF(EXACT($A$22,$P24),$O24,0) -> #VALUE! | AY24: =IF(ISERR(AX24),0,AX24) -> 0 | AZ24: =IF(EXACT($A$23,$P24),$O24,0) -> #VALUE! | BA24: =IF(ISERR(AZ24),0,AZ24) -> 0 | BB24: =IF(EXACT($A$24,$P24),$O24,0) -> #VALUE! | BC24: =IF(ISERR(BB24),0,BB24) -> 0 | BD24: =IF(EXACT($A$25,$P24),$O24,0) -> #VALUE! | BE24: =IF(ISERR(BD24),0,BD24) -> 0 | BF24: =IF(EXACT($A$26,$P24),$O24,0) -> #VALUE! | BG24: =IF(ISERR(BF24),0,BF24) -> 0 | BH24: =IF(EXACT($A$27,$P24),$O24,0) -> #VALUE! | BI24: =IF(ISERR(BH24),0,BH24) -> 0 | BJ24: =IF(EXACT($A$28,$P24),$O24,0) -> #VALUE! | BK24: =IF(ISERR(BJ24),0,BJ24) -> 0 | BL24: =IF(EXACT($A$29,$P24),$O24,0) -> #VALUE! | BM24: =IF(ISERR(BL24),0,BL24) -> 0 | BN24: =IF(EXACT($A$30,$P24),$O24,0) -> #VALUE! | BO24: =IF(ISERR(BN24),0,BN24) -> 0
E25: =IF(AND(C25=0,D25=0)," ",+C25*D25) | F25: =IF(AND(C25=0,D25=0)," ",+BE32) | G25: =IF(AND(C25=0,D25=0)," ",+E25+F25) | J25: =IF(AND(C25=0,D25=0)," ",+G25*I25) | M25: =IF(AND(C25=0,D25=0)," ",+K48) | N25: =IF(AND(C25=0,D25=0)," ",O48) | O25: =IF(AND(C25=0,D25=0)," ",+G25*(1-(N25/100))) | R25: =K25+0.25*(1-(1-$M$6/M25)^2.67) -> #DIV/0! | S25: =($M$4+K25*$M$6)/$M$6 -> 0.125 | T25: =($M$4/($M$4+$M$6*K25))*(0.56/$M$5*S25^1.667*L25^0.5*$M$6^2.667)/J25 -> #DIV/0! | U25: =K25+($M$4/$M$6)*T25 -> #DIV/0! | V25: =IF(B25>=15,0.54*J25^0.42*L25^0.3*(1/($M$5*U25))^0.6,W25) -> #DIV/0! | W25: =0.58*J25^0.42*L25^0.3*(1/($M$5*U25))^0.6 -> #DIV/0! | X25: =IF($M$4=0,0.6*J25^0.42*L25^0.3*(1/($M$5*U25))^0.6,V25) -> #DIV/0! | Y25: =IF(B25>X25,1,1-(1-B25/X25)^1.8) -> #DIV/0! | AB25: =IF(EXACT($A$11,$P25),$O25,0) -> #VALUE! | AC25: =IF(ISERR(AB25),0,AB25) -> 0 | AD25: =IF(EXACT($A$12,$P25),$O25,0) -> #VALUE! | AE25: =IF(ISERR(AD25),0,AD25) -> 0 | AF25: =IF(EXACT($A$13,$P25),$O25,0) -> #VALUE! | AG25: =IF(ISERR(AF25),0,AF25) -> 0 | AH25: =IF(EXACT($A$14,$P25),$O25,0) -> #VALUE! | AI25: =IF(ISERR(AH25),0,AH25) -> 0 | AJ25: =IF(EXACT($A$15,$P25),$O25,0) -> #VALUE! | AK25: =IF(ISERR(AJ25),0,AJ25) -> 0 | AL25: =IF(EXACT($A$16,$P25),$O25,0) -> #VALUE! | AM25: =IF(ISERR(AL25),0,AL25) -> 0 | AN25: =IF(EXACT($A$17,$P25),$O25,0) -> #VALUE! | AO25: =IF(ISERR(AN25),0,AN25) -> 0 | AP25: =IF(EXACT($A$18,$P25),$O25,0) -> #VALUE! | AQ25: =IF(ISERR(AP25),0,AP25) -> 0 | AR25: =IF(EXACT($A$19,$P25),$O25,0) -> #VALUE! | AS25: =IF(ISERR(AR25),0,AR25) -> 0 | AT25: =IF(EXACT($A$20,$P25),$O25,0) -> #VALUE! | AU25: =IF(ISERR(AT25),0,AT25) -> 0 | AV25: =IF(EXACT($A$21,$P25),$O25,0) -> #VALUE! | AW25: =IF(ISERR(AV25),0,AV25) -> 0 | AX25: =IF(EXACT($A$22,$P25),$O25,0) -> #VALUE! | AY25: =IF(ISERR(AX25),0,AX25) -> 0 | AZ25: =IF(EXACT($A$23,$P25),$O25,0) -> #VALUE! | BA25: =IF(ISERR(AZ25),0,AZ25) -> 0 | BB25: =IF(EXACT($A$24,$P25),$O25,0) -> #VALUE! | BC25: =IF(ISERR(BB25),0,BB25) -> 0 | BD25: =IF(EXACT($A$25,$P25),$O25,0) -> #VALUE! | BE25: =IF(ISERR(BD25),0,BD25) -> 0 | BF25: =IF(EXACT($A$26,$P25),$O25,0) -> #VALUE! | BG25: =IF(ISERR(BF25),0,BF25) -> 0 | BH25: =IF(EXACT($A$27,$P25),$O25,0) -> #VALUE! | BI25: =IF(ISERR(BH25),0,BH25) -> 0 | BJ25: =IF(EXACT($A$28,$P25),$O25,0) -> #VALUE! | BK25: =IF(ISERR(BJ25),0,BJ25) -> 0 | BL25: =IF(EXACT($A$29,$P25),$O25,0) -> #VALUE! | BM25: =IF(ISERR(BL25),0,BL25) -> 0 | BN25: =IF(EXACT($A$30,$P25),$O25,0) -> #VALUE! | BO25: =IF(ISERR(BN25),0,BN25) -> 0
E26: =IF(AND(C26=0,D26=0)," ",+C26*D26) | F26: =IF(AND(C26=0,D26=0)," ",+BG32) | G26: =IF(AND(C26=0,D26=0)," ",+E26+F26) | J26: =IF(AND(C26=0,D26=0)," ",+G26*I26) | M26: =IF(AND(C26=0,D26=0)," ",+K49) | N26: =IF(AND(C26=0,D26=0)," ",O49) | O26: =IF(AND(C26=0,D26=0)," ",+G26*(1-(N26/100))) | R26: =K26+0.25*(1-(1-$M$6/M26)^2.67) -> #DIV/0! | S26: =($M$4+K26*$M$6)/$M$6 -> 0.125 | T26: =($M$4/($M$4+$M$6*K26))*(0.56/$M$5*S26^1.667*L26^0.5*$M$6^2.667)/J26 -> #DIV/0! | U26: =K26+($M$4/$M$6)*T26 -> #DIV/0! | V26: =IF(B26>=15,0.54*J26^0.42*L26^0.3*(1/($M$5*U26))^0.6,W26) -> #DIV/0! | W26: =0.58*J26^0.42*L26^0.3*(1/($M$5*U26))^0.6 -> #DIV/0! | X26: =IF($M$4=0,0.6*J26^0.42*L26^0.3*(1/($M$5*U26))^0.6,V26) -> #DIV/0! | Y26: =IF(B26>X26,1,1-(1-B26/X26)^1.8) -> #DIV/0! | AB26: =IF(EXACT($A$11,$P26),$O26,0) -> #VALUE! | AC26: =IF(ISERR(AB26),0,AB26) -> 0 | AD26: =IF(EXACT($A$12,$P26),$O26,0) -> #VALUE! | AE26: =IF(ISERR(AD26),0,AD26) -> 0 | AF26: =IF(EXACT($A$13,$P26),$O26,0) -> #VALUE! | AG26: =IF(ISERR(AF26),0,AF26) -> 0 | AH26: =IF(EXACT($A$14,$P26),$O26,0) -> #VALUE! | AI26: =IF(ISERR(AH26),0,AH26) -> 0 | AJ26: =IF(EXACT($A$15,$P26),$O26,0) -> #VALUE! | AK26: =IF(ISERR(AJ26),0,AJ26) -> 0 | AL26: =IF(EXACT($A$16,$P26),$O26,0) -> #VALUE! | AM26: =IF(ISERR(AL26),0,AL26) -> 0 | AN26: =IF(EXACT($A$17,$P26),$O26,0) -> #VALUE! | AO26: =IF(ISERR(AN26),0,AN26) -> 0 | AP26: =IF(EXACT($A$18,$P26),$O26,0) -> #VALUE! | AQ26: =IF(ISERR(AP26),0,AP26) -> 0 | AR26: =IF(EXACT($A$19,$P26),$O26,0) -> #VALUE! | AS26: =IF(ISERR(AR26),0,AR26) -> 0 | AT26: =IF(EXACT($A$20,$P26),$O26,0) -> #VALUE! | AU26: =IF(ISERR(AT26),0,AT26) -> 0 | AV26: =IF(EXACT($A$21,$P26),$O26,0) -> #VALUE! | AW26: =IF(ISERR(AV26),0,AV26) -> 0 | AX26: =IF(EXACT($A$22,$P26),$O26,0) -> #VALUE! | AY26: =IF(ISERR(AX26),0,AX26) -> 0 | AZ26: =IF(EXACT($A$23,$P26),$O26,0) -> #VALUE! | BA26: =IF(ISERR(AZ26),0,AZ26) -> 0 | BB26: =IF(EXACT($A$24,$P26),$O26,0) -> #VALUE! | BC26: =IF(ISERR(BB26),0,BB26) -> 0 | BD26: =IF(EXACT($A$25,$P26),$O26,0) -> #VALUE! | BE26: =IF(ISERR(BD26),0,BD26) -> 0 | BF26: =IF(EXACT($A$26,$P26),$O26,0) -> #VALUE! | BG26: =IF(ISERR(BF26),0,BF26) -> 0 | BH26: =IF(EXACT($A$27,$P26),$O26,0) -> #VALUE! | BI26: =IF(ISERR(BH26),0,BH26) -> 0 | BJ26: =IF(EXACT($A$28,$P26),$O26,0) -> #VALUE! | BK26: =IF(ISERR(BJ26),0,BJ26) -> 0 | BL26: =IF(EXACT($A$29,$P26),$O26,0) -> #VALUE! | BM26: =IF(ISERR(BL26),0,BL26) -> 0 | BN26: =IF(EXACT($A$30,$P26),$O26,0) -> #VALUE! | BO26: =IF(ISERR(BN26),0,BN26) -> 0
E27: =IF(AND(C27=0,D27=0)," ",+C27*D27) | F27: =IF(AND(C27=0,D27=0)," ",+BI32) | G27: =IF(AND(C27=0,D27=0)," ",+E27+F27) | J27: =IF(AND(C27=0,D27=0)," ",+G27*I27) | M27: =IF(AND(C27=0,D27=0)," ",+K50) | N27: =IF(AND(C27=0,D27=0)," ",O50) | O27: =IF(AND(C27=0,D27=0)," ",+G27*(1-(N27/100))) | R27: =K27+0.25*(1-(1-$M$6/M27)^2.67) -> #DIV/0! | S27: =($M$4+K27*$M$6)/$M$6 -> 0.125 | T27: =($M$4/($M$4+$M$6*K27))*(0.56/$M$5*S27^1.667*L27^0.5*$M$6^2.667)/J27 -> #DIV/0! | U27: =K27+($M$4/$M$6)*T27 -> #DIV/0! | V27: =IF(B27>=15,0.54*J27^0.42*L27^0.3*(1/($M$5*U27))^0.6,W27) -> #DIV/0! | W27: =0.58*J27^0.42*L27^0.3*(1/($M$5*U27))^0.6 -> #DIV/0! | X27: =IF($M$4=0,0.6*J27^0.42*L27^0.3*(1/($M$5*U27))^0.6,V27) -> #DIV/0! | Y27: =IF(B27>X27,1,1-(1-B27/X27)^1.8) -> #DIV/0! | AB27: =IF(EXACT($A$11,$P27),$O27,0) -> #VALUE! | AC27: =IF(ISERR(AB27),0,AB27) -> 0 | AD27: =IF(EXACT($A$12,$P27),$O27,0) -> #VALUE! | AE27: =IF(ISERR(AD27),0,AD27) -> 0 | AF27: =IF(EXACT($A$13,$P27),$O27,0) -> #VALUE! | AG27: =IF(ISERR(AF27),0,AF27) -> 0 | AH27: =IF(EXACT($A$14,$P27),$O27,0) -> #VALUE! | AI27: =IF(ISERR(AH27),0,AH27) -> 0 | AJ27: =IF(EXACT($A$15,$P27),$O27,0) -> #VALUE! | AK27: =IF(ISERR(AJ27),0,AJ27) -> 0 | AL27: =IF(EXACT($A$16,$P27),$O27,0) -> #VALUE! | AM27: =IF(ISERR(AL27),0,AL27) -> 0 | AN27: =IF(EXACT($A$17,$P27),$O27,0) -> #VALUE! | AO27: =IF(ISERR(AN27),0,AN27) -> 0 | AP27: =IF(EXACT($A$18,$P27),$O27,0) -> #VALUE! | AQ27: =IF(ISERR(AP27),0,AP27) -> 0 | AR27: =IF(EXACT($A$19,$P27),$O27,0) -> #VALUE! | AS27: =IF(ISERR(AR27),0,AR27) -> 0 | AT27: =IF(EXACT($A$20,$P27),$O27,0) -> #VALUE! | AU27: =IF(ISERR(AT27),0,AT27) -> 0 | AV27: =IF(EXACT($A$21,$P27),$O27,0) -> #VALUE! | AW27: =IF(ISERR(AV27),0,AV27) -> 0 | AX27: =IF(EXACT($A$22,$P27),$O27,0) -> #VALUE! | AY27: =IF(ISERR(AX27),0,AX27) -> 0 | AZ27: =IF(EXACT($A$23,$P27),$O27,0) -> #VALUE! | BA27: =IF(ISERR(AZ27),0,AZ27) -> 0 | BB27: =IF(EXACT($A$24,$P27),$O27,0) -> #VALUE! | BC27: =IF(ISERR(BB27),0,BB27) -> 0 | BD27: =IF(EXACT($A$25,$P27),$O27,0) -> #VALUE! | BE27: =IF(ISERR(BD27),0,BD27) -> 0 | BF27: =IF(EXACT($A$26,$P27),$O27,0) -> #VALUE! | BG27: =IF(ISERR(BF27),0,BF27) -> 0 | BH27: =IF(EXACT($A$27,$P27),$O27,0) -> #VALUE! | BI27: =IF(ISERR(BH27),0,BH27) -> 0 | BJ27: =IF(EXACT($A$28,$P27),$O27,0) -> #VALUE! | BK27: =IF(ISERR(BJ27),0,BJ27) -> 0 | BL27: =IF(EXACT($A$29,$P27),$O27,0) -> #VALUE! | BM27: =IF(ISERR(BL27),0,BL27) -> 0 | BN27: =IF(EXACT($A$30,$P27),$O27,0) -> #VALUE! | BO27: =IF(ISERR(BN27),0,BN27) -> 0
E28: =IF(AND(C28=0,D28=0)," ",+C28*D28) | F28: =IF(AND(C28=0,D28=0)," ",+BK32) | G28: =IF(AND(C28=0,D28=0)," ",+E28+F28) | J28: =IF(AND(C28=0,D28=0)," ",+G28*I28) | M28: =IF(AND(C28=0,D28=0)," ",+K51) | N28: =IF(AND(C28=0,D28=0)," ",O51) | O28: =IF(AND(C28=0,D28=0)," ",+G28*(1-(N28/100))) | R28: =K28+0.25*(1-(1-$M$6/M28)^2.67) -> #DIV/0! | S28: =($M$4+K28*$M$6)/$M$6 -> 0.125 | T28: =($M$4/($M$4+$M$6*K28))*(0.56/$M$5*S28^1.667*L28^0.5*$M$6^2.667)/J28 -> #DIV/0! | U28: =K28+($M$4/$M$6)*T28 -> #DIV/0! | V28: =IF(B28>=15,0.54*J28^0.42*L28^0.3*(1/($M$5*U28))^0.6,W28) -> #DIV/0! | W28: =0.58*J28^0.42*L28^0.3*(1/($M$5*U28))^0.6 -> #DIV/0! | X28: =IF($M$4=0,0.6*J28^0.42*L28^0.3*(1/($M$5*U28))^0.6,V28) -> #DIV/0! | Y28: =IF(B28>X28,1,1-(1-B28/X28)^1.8) -> #DIV/0! | AB28: =IF(EXACT($A$11,$P28),$O28,0) -> #VALUE! | AC28: =IF(ISERR(AB28),0,AB28) -> 0 | AD28: =IF(EXACT($A$12,$P28),$O28,0) -> #VALUE! | AE28: =IF(ISERR(AD28),0,AD28) -> 0 | AF28: =IF(EXACT($A$13,$P28),$O28,0) -> #VALUE! | AG28: =IF(ISERR(AF28),0,AF28) -> 0 | AH28: =IF(EXACT($A$14,$P28),$O28,0) -> #VALUE! | AI28: =IF(ISERR(AH28),0,AH28) -> 0 | AJ28: =IF(EXACT($A$15,$P28),$O28,0) -> #VALUE! | AK28: =IF(ISERR(AJ28),0,AJ28) -> 0 | AL28: =IF(EXACT($A$16,$P28),$O28,0) -> #VALUE! | AM28: =IF(ISERR(AL28),0,AL28) -> 0 | AN28: =IF(EXACT($A$17,$P28),$O28,0) -> #VALUE! | AO28: =IF(ISERR(AN28),0,AN28) -> 0 | AP28: =IF(EXACT($A$18,$P28),$O28,0) -> #VALUE! | AQ28: =IF(ISERR(AP28),0,AP28) -> 0 | AR28: =IF(EXACT($A$19,$P28),$O28,0) -> #VALUE! | AS28: =IF(ISERR(AR28),0,AR28) -> 0 | AT28: =IF(EXACT($A$20,$P28),$O28,0) -> #VALUE! | AU28: =IF(ISERR(AT28),0,AT28) -> 0 | AV28: =IF(EXACT($A$21,$P28),$O28,0) -> #VALUE! | AW28: =IF(ISERR(AV28),0,AV28) -> 0 | AX28: =IF(EXACT($A$22,$P28),$O28,0) -> #VALUE! | AY28: =IF(ISERR(AX28),0,AX28) -> 0 | AZ28: =IF(EXACT($A$23,$P28),$O28,0) -> #VALUE! | BA28: =IF(ISERR(AZ28),0,AZ28) -> 0 | BB28: =IF(EXACT($A$24,$P28),$O28,0) -> #VALUE! | BC28: =IF(ISERR(BB28),0,BB28) -> 0 | BD28: =IF(EXACT($A$25,$P28),$O28,0) -> #VALUE! | BE28: =IF(ISERR(BD28),0,BD28) -> 0 | BF28: =IF(EXACT($A$26,$P28),$O28,0) -> #VALUE! | BG28: =IF(ISERR(BF28),0,BF28) -> 0 | BH28: =IF(EXACT($A$27,$P28),$O28,0) -> #VALUE! | BI28: =IF(ISERR(BH28),0,BH28) -> 0 | BJ28: =IF(EXACT($A$28,$P28),$O28,0) -> #VALUE! | BK28: =IF(ISERR(BJ28),0,BJ28) -> 0 | BL28: =IF(EXACT($A$29,$P28),$O28,0) -> #VALUE! | BM28: =IF(ISERR(BL28),0,BL28) -> 0 | BN28: =IF(EXACT($A$30,$P28),$O28,0) -> #VALUE! | BO28: =IF(ISERR(BN28),0,BN28) -> 0
E29: =IF(AND(C29=0,D29=0)," ",+C29*D29) | F29: =IF(AND(C29=0,D29=0)," ",+BM32) | G29: =IF(AND(C29=0,D29=0)," ",+E29+F29) | J29: =IF(AND(C29=0,D29=0)," ",+G29*I29) | M29: =IF(AND(C29=0,D29=0)," ",+K52) | N29: =IF(AND(C29=0,D29=0)," ",O52) | O29: =IF(AND(C29=0,D29=0)," ",+G29*(1-(N29/100))) | R29: =K29+0.25*(1-(1-$M$6/M29)^2.67) -> #DIV/0! | S29: =($M$4+K29*$M$6)/$M$6 -> 0.125 | T29: =($M$4/($M$4+$M$6*K29))*(0.56/$M$5*S29^1.667*L29^0.5*$M$6^2.667)/J29 -> #DIV/0! | U29: =K29+($M$4/$M$6)*T29 -> #DIV/0! | V29: =IF(B29>=15,0.54*J29^0.42*L29^0.3*(1/($M$5*U29))^0.6,W29) -> #DIV/0! | W29: =0.58*J29^0.42*L29^0.3*(1/($M$5*U29))^0.6 -> #DIV/0! | X29: =IF($M$4=0,0.6*J29^0.42*L29^0.3*(1/($M$5*U29))^0.6,V29) -> #DIV/0! | Y29: =IF(B29>X29,1,1-(1-B29/X29)^1.8) -> #DIV/0! | AB29: =IF(EXACT($A$11,$P29),$O29,0) -> #VALUE! | AC29: =IF(ISERR(AB29),0,AB29) -> 0 | AD29: =IF(EXACT($A$12,$P29),$O29,0) -> #VALUE! | AE29: =IF(ISERR(AD29),0,AD29) -> 0 | AF29: =IF(EXACT($A$13,$P29),$O29,0) -> #VALUE! | AG29: =IF(ISERR(AF29),0,AF29) -> 0 | AH29: =IF(EXACT($A$14,$P29),$O29,0) -> #VALUE! | AI29: =IF(ISERR(AH29),0,AH29) -> 0 | AJ29: =IF(EXACT($A$15,$P29),$O29,0) -> #VALUE! | AK29: =IF(ISERR(AJ29),0,AJ29) -> 0 | AL29: =IF(EXACT($A$16,$P29),$O29,0) -> #VALUE! | AM29: =IF(ISERR(AL29),0,AL29) -> 0 | AN29: =IF(EXACT($A$17,$P29),$O29,0) -> #VALUE! | AO29: =IF(ISERR(AN29),0,AN29) -> 0 | AP29: =IF(EXACT($A$18,$P29),$O29,0) -> #VALUE! | AQ29: =IF(ISERR(AP29),0,AP29) -> 0 | AR29: =IF(EXACT($A$19,$P29),$O29,0) -> #VALUE! | AS29: =IF(ISERR(AR29),0,AR29) -> 0 | AT29: =IF(EXACT($A$20,$P29),$O29,0) -> #VALUE! | AU29: =IF(ISERR(AT29),0,AT29) -> 0 | AV29: =IF(EXACT($A$21,$P29),$O29,0) -> #VALUE! | AW29: =IF(ISERR(AV29),0,AV29) -> 0 | AX29: =IF(EXACT($A$22,$P29),$O29,0) -> #VALUE! | AY29: =IF(ISERR(AX29),0,AX29) -> 0 | AZ29: =IF(EXACT($A$23,$P29),$O29,0) -> #VALUE! | BA29: =IF(ISERR(AZ29),0,AZ29) -> 0 | BB29: =IF(EXACT($A$24,$P29),$O29,0) -> #VALUE! | BC29: =IF(ISERR(BB29),0,BB29) -> 0 | BD29: =IF(EXACT($A$25,$P29),$O29,0) -> #VALUE! | BE29: =IF(ISERR(BD29),0,BD29) -> 0 | BF29: =IF(EXACT($A$26,$P29),$O29,0) -> #VALUE! | BG29: =IF(ISERR(BF29),0,BF29) -> 0 | BH29: =IF(EXACT($A$27,$P29),$O29,0) -> #VALUE! | BI29: =IF(ISERR(BH29),0,BH29) -> 0 | BJ29: =IF(EXACT($A$28,$P29),$O29,0) -> #VALUE! | BK29: =IF(ISERR(BJ29),0,BJ29) -> 0 | BL29: =IF(EXACT($A$29,$P29),$O29,0) -> #VALUE! | BM29: =IF(ISERR(BL29),0,BL29) -> 0 | BN29: =IF(EXACT($A$30,$P29),$O29,0) -> #VALUE! | BO29: =IF(ISERR(BN29),0,BN29) -> 0
E30: =IF(AND(C30=0,D30=0)," ",+C30*D30) | F30: =IF(AND(C30=0,D30=0)," ",BO32) | G30: =IF(AND(C30=0,D30=0)," ",+E30+F30) | J30: =IF(AND(C30=0,D30=0)," ",+G30*I30) | M30: =IF(AND(C30=0,D30=0)," ",+K53) | N30: =IF(AND(C30=0,D30=0)," ",O53) | O30: =IF(AND(C30=0,D30=0)," ",+G30*(1-(N30/100))) | R30: =K30+0.25*(1-(1-$M$6/M30)^2.67) -> #DIV/0! | S30: =($M$4+K30*$M$6)/$M$6 -> 0.125 | T30: =($M$4/($M$4+$M$6*K30))*(0.56/$M$5*S30^1.667*L30^0.5*$M$6^2.667)/J30 -> #DIV/0! | U30: =K30+($M$4/$M$6)*T30 -> #DIV/0! | V30: =IF(B30>=15,0.54*J30^0.42*L30^0.3*(1/($M$5*U30))^0.6,W30) -> #DIV/0! | W30: =0.58*J30^0.42*L30^0.3*(1/($M$5*U30))^0.6 -> #DIV/0! | X30: =IF($M$4=0,0.6*J30^0.42*L30^0.3*(1/($M$5*U30))^0.6,V30) -> #DIV/0! | Y30: =IF(B30>X30,1,1-(1-B30/X30)^1.8) -> #DIV/0! | AB30: =IF(EXACT($A$11,$P30),$O30,0) -> 0 | AC30: =IF(ISERR(AB30),0,AB30) -> 0 | AD30: =IF(EXACT($A$12,$P30),$O30,0) -> #VALUE! | AE30: =IF(ISERR(AD30),0,AD30) -> 0 | AF30: =IF(EXACT($A$13,$P30),$O30,0) -> #VALUE! | AG30: =IF(ISERR(AF30),0,AF30) -> 0 | AH30: =IF(EXACT($A$14,$P30),$O30,0) -> #VALUE! | AI30: =IF(ISERR(AH30),0,AH30) -> 0 | AJ30: =IF(EXACT($A$15,$P30),$O30,0) -> #VALUE! | AK30: =IF(ISERR(AJ30),0,AJ30) -> 0 | AL30: =IF(EXACT($A$16,$P30),$O30,0) -> #VALUE! | AM30: =IF(ISERR(AL30),0,AL30) -> 0 | AN30: =IF(EXACT($A$17,$P30),$O30,0) -> #VALUE! | AO30: =IF(ISERR(AN30),0,AN30) -> 0 | AP30: =IF(EXACT($A$18,$P30),$O30,0) -> #VALUE! | AQ30: =IF(ISERR(AP30),0,AP30) -> 0 | AR30: =IF(EXACT($A$19,$P30),$O30,0) -> #VALUE! | AS30: =IF(ISERR(AR30),0,AR30) -> 0 | AT30: =IF(EXACT($A$20,$P30),$O30,0) -> #VALUE! | AU30: =IF(ISERR(AT30),0,AT30) -> 0 | AV30: =IF(EXACT($A$21,$P30),$O30,0) -> #VALUE! | AW30: =IF(ISERR(AV30),0,AV30) -> 0 | AX30: =IF(EXACT($A$22,$P30),$O30,0) -> #VALUE! | AY30: =IF(ISERR(AX30),0,AX30) -> 0 | AZ30: =IF(EXACT($A$23,$P30),$O30,0) -> #VALUE! | BA30: =IF(ISERR(AZ30),0,AZ30) -> 0 | BB30: =IF(EXACT($A$24,$P30),$O30,0) -> #VALUE! | BC30: =IF(ISERR(BB30),0,BB30) -> 0 | BD30: =IF(EXACT($A$25,$P30),$O30,0) -> #VALUE! | BE30: =IF(ISERR(BD30),0,BD30) -> 0 | BF30: =IF(EXACT($A$26,$P30),$O30,0) -> #VALUE! | BG30: =IF(ISERR(BF30),0,BF30) -> 0 | BH30: =IF(EXACT($A$27,$P30),$O30,0) -> #VALUE! | BI30: =IF(ISERR(BH30),0,BH30) -> 0 | BJ30: =IF(EXACT($A$28,$P30),$O30,0) -> #VALUE! | BK30: =IF(ISERR(BJ30),0,BJ30) -> 0 | BL30: =IF(EXACT($A$29,$P30),$O30,0) -> #VALUE! | BM30: =IF(ISERR(BL30),0,BL30) -> 0 | BN30: =IF(EXACT($A$30,$P30),$O30,0) -> #VALUE! | BO30: =IF(ISERR(BN30),0,BN30) -> 0
C32: Alt - E : Save File and Exit 123 | K32: spread | M32: spread | N32: spread | O32: % intercept | AC32: =SUM(AC11:AC30) -> 0 | AE32: =SUM(AE11:AE30) -> 0 | AG32: =SUM(AG11:AG30) -> 0 | AI32: =SUM(AI11:AI30) -> 0 | AK32: =SUM(AK11:AK30) -> 0 | AM32: =SUM(AM11:AM30) -> 0 | AO32: =SUM(AO11:AO30) -> 0 | AQ32: =SUM(AQ11:AQ30) -> 0 | AS32: =SUM(AS11:AS30) -> 0 | AU32: =SUM(AU11:AU30) -> 0 | AW32: =SUM(AW11:AW30) -> 0 | AY32: =SUM(AY11:AY30) -> 0 | BA32: =SUM(BA11:BA30) -> 0 | BC32: =SUM(BC11:BC30) -> 0 | BE32: =SUM(BE11:BE30) -> 0 | BG32: =SUM(BG11:BG30) -> 0 | BI32: =SUM(BI11:BI30) -> 0 | BK32: =SUM(BK11:BK30) -> 0 | BM32: =SUM(BM11:BM30) -> 0 | BO32: =SUM(BO11:BO30) -> 0
C33: Alt - C : Create Separate Input Data File | K33: used | L33: SUMP | M33: as weir | N33: on-grade | O33: on-grade
C34: Alt - R : Retrieve Input Data File | K34: =IF(ISERR(L34),N34,L34) -> 4.6717466 | L34: =IF(EXACT($L$33,$L11),$M34,0) -> #VALUE! | M34: =(J11/(2.3*(B11+1.8*$M$6)))^0.667/K11 -> 4.0767511 | N34: =((J11*$M$5)/(0.56*K11^1.67*L11^0.5))^0.3745 -> 4.6717466 | O34: =IF(M11=M34,100,+Y11*100) -> 94.388275
C35: Alt - P : Print Results | K35: =IF(ISERR(L35),N35,L35) -> #DIV/0! | L35: =IF(EXACT($L$33,$L12),$M35,0) -> #VALUE! | M35: =(J12/(2.3*(B12+1.8*$M$6)))^0.667/K12 -> #DIV/0! | N35: =((J12*$M$5)/(0.56*K12^1.67*L12^0.5))^0.3745 -> #DIV/0! | O35: =IF(M12=M35,100,+Y12*100) -> #DIV/0!
K36: =IF(ISERR(L36),N36,L36) -> #DIV/0! | L36: =IF(EXACT($L$33,$L13),$M36,0) -> #VALUE! | M36: =(J13/(2.3*(B13+1.8*$M$6)))^0.667/K13 -> #DIV/0! | N36: =((J13*$M$5)/(0.56*K13^1.67*L13^0.5))^0.3745 -> #DIV/0! | O36: =IF(M13=M36,100,+Y13*100) -> #DIV/0!
K37: =IF(ISERR(L37),N37,L37) -> #DIV/0! | L37: =IF(EXACT($L$33,$L14),$M37,0) -> #VALUE! | M37: =(J14/(2.3*(B14+1.8*$M$6)))^0.667/K14 -> #DIV/0! | N37: =((J14*$M$5)/(0.56*K14^1.67*L14^0.5))^0.3745 -> #DIV/0! | O37: =IF(M14=M37,100,+Y14*100) -> #DIV/0!
B38: \0 | C38: {WINDOWSOFF} | K38: =IF(ISERR(L38),N38,L38) -> #DIV/0! | L38: =IF(EXACT($L$33,$L15),$M38,0) -> #VALUE! | M38: =(J15/(2.3*(B15+1.8*$M$6)))^0.667/K15 -> #DIV/0! | N38: =((J15*$M$5)/(0.56*K15^1.67*L15^0.5))^0.3745 -> #DIV/0! | O38: =IF(M15=M38,100,+Y15*100) -> #DIV/0!
C39: /AA{R 4}~NQ | K39: =IF(ISERR(L39),N39,L39) -> #DIV/0! | L39: =IF(EXACT($L$33,$L16),$M39,0) -> #VALUE! | M39: =(J16/(2.3*(B16+1.8*$M$6)))^0.667/K16 -> #DIV/0! | N39: =((J16*$M$5)/(0.56*K16^1.67*L16^0.5))^0.3745 -> #DIV/0! | O39: =IF(M16=M39,100,+Y16*100) -> #DIV/0!
C40: {HOME} | F40: \E | G40: {WINDOWSOFF} | K40: =IF(ISERR(L40),N40,L40) -> #DIV/0! | L40: =IF(EXACT($L$33,$L17),$M40,0) -> #VALUE! | M40: =(J17/(2.3*(B17+1.8*$M$6)))^0.667/K17 -> #DIV/0! | N40: =((J17*$M$5)/(0.56*K17^1.67*L17^0.5))^0.3745 -> #DIV/0! | O40: =IF(M17=M40,100,+Y17*100) -> #DIV/0!
C41: {R 2}{D 3} | G41: /fs~r | K41: =IF(ISERR(L41),N41,L41) -> #DIV/0! | L41: =IF(EXACT($L$33,$L18),$M41,0) -> #VALUE! | M41: =(J18/(2.3*(B18+1.8*$M$6)))^0.667/K18 -> #DIV/0! | N41: =((J18*$M$5)/(0.56*K18^1.67*L18^0.5))^0.3745 -> #DIV/0! | O41: =IF(M18=M41,100,+Y18*100) -> #DIV/0!
C42: /WGPE | G42: /ad~q | K42: =IF(ISERR(L42),N42,L42) -> #DIV/0! | L42: =IF(EXACT($L$33,$L19),$M42,0) -> #VALUE! | M42: =(J19/(2.3*(B19+1.8*$M$6)))^0.667/K19 -> #DIV/0! | N42: =((J19*$M$5)/(0.56*K19^1.67*L19^0.5))^0.3745 -> #DIV/0! | O42: =IF(M19=M42,100,+Y19*100) -> #DIV/0!
G43: /qy | K43: =IF(ISERR(L43),N43,L43) -> #DIV/0! | L43: =IF(EXACT($L$33,$L20),$M43,0) -> #VALUE! | M43: =(J20/(2.3*(B20+1.8*$M$6)))^0.667/K20 -> #DIV/0! | N43: =((J20*$M$5)/(0.56*K20^1.67*L20^0.5))^0.3745 -> #DIV/0! | O43: =IF(M20=M43,100,+Y20*100) -> #DIV/0!
K44: =IF(ISERR(L44),N44,L44) -> #DIV/0! | L44: =IF(EXACT($L$33,$L21),$M44,0) -> #VALUE! | M44: =(J21/(2.3*(B21+1.8*$M$6)))^0.667/K21 -> #DIV/0! | N44: =((J21*$M$5)/(0.56*K21^1.67*L21^0.5))^0.3745 -> #DIV/0! | O44: =IF(M21=M44,100,+Y21*100) -> #DIV/0!
...

Sheet Rationals-MCDOT
A1: STANTEC | J1: STANTEC | S1: STANTEC
A2: PROJECT: | B2: Bladensburg SD-1 | J2: PROJECT: | K2: Bladensburg SD-1 | S2: PROJECT: | T2: ESSN GREENWAY
A3: STANTEC JOB # : | B3: 203403586 | J3: STANTEC JOB # : | K3: 203403586 | S3: STANTEC JOB # : | T3: 2026213122
B5: EX-I-1 | F5: BY | G5: DATE | K5: EX-I-2 | O5: BY | P5: DATE | T5: I-1 | X5: BY | Y5: DATE
E6: COMPUTED | F6: KCY | G6: 46239 | N6: COMPUTED | O6: KCY | P6: 46239 | T6: Grove Street 1111+25 LT | W6: COMPUTED | X6: ALM | Y6: 45028
E7: CHECKED | N7: CHECKED | W7: CHECKED | X7: SMH | Y7: 45260
A9: SOIL TYPE | B9: % SLOPE | C9: LANDUSE | D9: AREA (SF) | E9: 2, 10-YR STORM | G9: 25-YR STORM | J9: SOIL TYPE | K9: % SLOPE | L9: LANDUSE | M9: AREA (SF) | N9: 2, 10-YR STORM | P9: 25-YR STORM | S9: SOIL TYPE | T9: % SLOPE | U9: LANDUSE | V9: AREA (SF) | W9: 2, 10-YR STORM | Y9: 25-YR STORM
E10: C | F10: CA | G10: C | H10: CA | N10: C | O10: CA | P10: C | Q10: CA | W10: C | X10: CA | Y10: C | Z10: CA
A11: --- | B11: --- | C11: Impervious | D11: 2209.54 | E11: 0.9 | F11: =D11*E11 -> 1988.586 | G11: 0.9 | H11: =D11*G11 -> 1988.586 | J11: --- | K11: --- | L11: Impervious | M11: 45469.71 | N11: 0.9 | O11: =M11*N11 -> 40922.739 | P11: 0.9 | Q11: =M11*P11 -> 40922.739 | S11: --- | T11: --- | U11: Impervious | V11: 6485.65 | W11: 0.9 | X11: =V11*W11 -> 5837.085 | Y11: 0.9 | Z11: =V11*Y11 -> 5837.085
A12: D | B12: 2-7% | C12: Open Space | D12: 184.74 | E12: 0.24 | F12: =D12*E12 -> 44.3376 | G12: 0.24 | H12: =D12*G12 -> 44.3376 | J12: D | K12: 2-7% | L12: Open Space | M12: 42247.93 | N12: 0.24 | O12: =M12*N12 -> 10139.503 | P12: 0.24 | Q12: =M12*P12 -> 10139.503 | S12: D | T12: 2-7% | U12: Open Space | V12: 1612.9236 | W12: 0.24 | X12: =V12*W12 -> 387.10166 | Y12: 0.24 | Z12: =V12*Y12 -> 387.10166
C20: TOTALS | D20: =SUM(D11:D19) -> 2394.28 | F20: =SUM(F11:F19) -> 2032.9236 | H20: =SUM(H11:H19) -> 2032.9236 | L20: TOTALS | M20: =SUM(M11:M19) -> 87717.64 | O20: =SUM(O11:O19) -> 51062.242 | Q20: =SUM(Q11:Q19) -> 51062.242 | U20: TOTALS | V20: =SUM(V11:V19) -> 8098.5736 | X20: =SUM(X11:X19) -> 6224.1867 | Z20: =SUM(Z11:Z19) -> 6224.1867
C22: COMPOSITE C FACTOR (2, 10-YR): | D22: =F20/D20 -> 0.84907513 | L22: COMPOSITE C FACTOR (2, 10-YR): | M22: =O20/M20 -> 0.58212057 | U22: COMPOSITE C FACTOR (2, 10-YR): | V22: =X20/V20 -> 0.76855345
C23: COMPOSITE C FACTOR (25-YR): | D23: =H20/D20 -> 0.84907513 | L23: COMPOSITE C FACTOR (25-YR): | M23: =Q20/M20 -> 0.58212057 | U23: COMPOSITE C FACTOR (25-YR): | V23: =Z20/V20 -> 0.76855345
A24: TIME OF CONCENTRATION | J24: TIME OF CONCENTRATION | S24: TIME OF CONCENTRATION
D25: STORM EVENT (YR) | E25: RAINFALL INTENSITY (IN/HR) | F25: DISCHARGE (CFS) | M25: STORM EVENT (YR) | N25: RAINFALL INTENSITY (IN/HR) | O25: DISCHARGE (CFS) | V25: STORM EVENT (YR) | W25: RAINFALL INTENSITY (IN/HR) | X25: DISCHARGE (CFS)
D27: 2 | E27: 4.01 | F27: =(F20*E27)/43560 -> 0.18714471 | M27: 2 | N27: 4.01 | O27: =(O20*N27)/43560 -> 4.7006334 | V27: 2 | W27: 4.01 | X27: =(X20*W27)/43560 -> 0.57297953
A28: Tc = | B28: 5 | C28: MIN | D28: 10 | E28: 6.68 | F28: =(F20*E28)/43560 -> 0.31175229 | J28: Tc = | K28: 10 | L28: MIN | M28: 10 | N28: 5.34 | O28: =(O20*N28)/43560 -> 6.2596964 | S28: Tc = | T28: 7 | U28: MIN | V28: 10 | W28: 6.15 | X28: =(X20*W28)/43560 -> 0.87875914
B29: [10+ (1300-100)/(60 * 7)] | D29: 25 | E29: 6.02 | F29: =(H20*E29)/43560 -> 0.28095041 | M29: 25 | N29: 6.02 | O29: =(Q20*N29)/43560 -> 7.0568112 | V29: 25 | W29: 6.02 | X29: =(Z20*W29)/43560 -> 0.86018374
A31: STANTEC | I31: STANTEC | R31: STANTEC
A32: PROJECT: | B32: Bladensburg SD-1 | I32: PROJECT: | J32: Bladensburg SD-1 | R32: PROJECT: | S32: Bladensburg SD-1
A33: STANTEC JOB # : | B33: 203403586 | I33: STANTEC JOB # : | J33: 203403586 | R33: STANTEC JOB # : | S33: 203403586
B35: I-2 | F35: BY | G35: DATE | J35: I-3 | N35: BY | O35: DATE | S35: I-4 | W35: BY | X35: DATE
E36: COMPUTED | F36: KCY | G36: 46239 | M36: COMPUTED | N36: KCY | O36: 46239 | V36: COMPUTED | W36: KCY | X36: 46239
E37: CHECKED | M37: CHECKED | V37: CHECKED
